Workbook

Sheet Participants
A1: Participant | B1: Total Fixations | C1: Total Fixation Duration (s) | D1: Mean Fixation Duration (ms) | E1: Image 1 | F1: Image 2 | G1: Image 3 | H1: Image 4 | I1: Image 5 | J1: Image 6 | K1: Image 7 | L1: Image 8 | M1: Image 9 | N1: Image 10 | O1: Image 11 | P1: Image 12 | Q1: Image 13 | R1: Image 14 | S1: Image 15 | T1: Image 16 | U1: Image 17 | V1: Image 18 | W1: Image 19 | X1: Image 20 | Y1: Image 21 | Z1: Image 22 | AA1: Image 23 | AB1: Image 24 | AC1: Image 25 | AD1: Image 26 | AE1: Image 27 | AF1: Image 28 | AG1: Image 29 | AH1: Image 30 | AI1: Image 31 | AJ1: Image 32 | AK1: Image 33 | AL1: Image 34 | AM1: Image 35 | AN1: Image 36 | AO1: Image 37 | AP1: Image 38 | AQ1: Image 39 | AR1: Image 40 | AS1: Image 41 | AT1: Image 42 | AU1: Image 43 | AV1: Image 44 | AW1: Image 45 | AX1: Image 46 | AY1: Image 47 | AZ1: Image 48 | BA1: Image 49 | BB1: Image 50 | BC1: Image 51 | BD1: Image 52 | BE1: Image 53 | BF1: Image 54 | BG1: Image 55 | BH1: Image 56 | BI1: Image 57 | BJ1: Image 58 | BK1: Image 59 | BL1: Image 60
A2: U1 | B2: 3145 | C2: 482.29564 | D2: 153.35314 | E2: 51 | F2: 58 | G2: 56 | H2: 51 | I2: 44 | J2: 53 | K2: 55 | L2: 52 | M2: 49 | N2: 56 | O2: 49 | P2: 54 | Q2: 43 | R2: 52 | S2: 53 | T2: 48 | U2: 56 | V2: 56 | W2: 49 | X2: 58 | Y2: 55 | Z2: 50 | AA2: 55 | AB2: 55 | AC2: 55 | AD2: 48 | AE2: 61 | AF2: 58 | AG2: 57 | AH2: 47 | AI2: 56 | AJ2: 50 | AK2: 47 | AL2: 51 | AM2: 42 | AN2: 55 | AO2: 56 | AP2: 50 | AQ2: 58 | AR2: 52 | AS2: 49 | AT2: 54 | AU2: 55 | AV2: 45 | AW2: 51 | AX2: 53 | AY2: 43 | AZ2: 52 | BA2: 51 | BB2: 52 | BC2: 57 | BD2: 50 | BE2: 55 | BF2: 54 | BG2: 58 | BH2: 50 | BI2: 55 | BJ2: 48 | BK2: 55 | BL2: 57
A3: U10 | B3: 2118 | C3: 374.09232 | D3: 176.62527 | E3: 43 | F3: 46 | G3: 43 | H3: 43 | I3: 40 | J3: 39 | K3: 49 | L3: 36 | M3: 40 | N3: 37 | O3: 42 | P3: 42 | Q3: 39 | R3: 29 | S3: 41 | T3: 41 | U3: 41 | V3: 45 | W3: 34 | X3: 45 | Y3: 33 | Z3: 45 | AA3: 38 | AB3: 33 | AC3: 39 | AD3: 32 | AE3: 44 | AF3: 52 | AG3: 44 | AH3: 28 | AI3: 49 | AJ3: 42 | AK3: 40 | AL3: 35 | AM3: 44 | AN3: 42 | AO3: 42 | AP3: 40 | AQ3: 42 | AR3: 38 | AS3: 37 | AT3: 40 | AU3: 45 | AV3: 24 | AW3: 0 | AX3: 0 | AY3: 0 | AZ3: 0 | BA3: 40 | BB3: 6 | BC3: 26 | BD3: 15 | BE3: 0 | BF3: 20 | BG3: 38 | BH3: 32 | BI3: 49 | BJ3: 44 | BK3: 49 | BL3: 36
A4: U11 | B4: 279 | C4: 34.607437 | D4: 124.04099 | E4: 0 | F4: 0 | G4: 0 | H4: 0 | I4: 0 | J4: 0 | K4: 0 | L4: 0 | M4: 0 | N4: 0 | O4: 0 | P4: 0 | Q4: 0 | R4: 38 | S4: 7 | T4: 6 | U4: 1 | V4: 13 | W4: 33 | X4: 24 | Y4: 3 | Z4: 12 | AA4: 12 | AB4: 3 | AC4: 0 | AD4: 0 | AE4: 12 | AF4: 18 | AG4: 0 | AH4: 1 | AI4: 2 | AJ4: 0 | AK4: 22 | AL4: 0 | AM4: 0 | AN4: 2 | AO4: 0 | AP4: 0 | AQ4: 0 | AR4: 2 | AS4: 8 | AT4: 0 | AU4: 0 | AV4: 9 | AW4: 0 | AX4: 1 | AY4: 4 | AZ4: 0 | BA4: 0 | BB4: 0 | BC4: 2 | BD4: 14 | BE4: 1 | BF4: 6 | BG4: 2 | BH4: 3 | BI4: 5 | BJ4: 12 | BK4: 1 | BL4: 0
A5: U12 | B5: 2954 | C5: 476.32541 | D5: 161.2476 | E5: 47 | F5: 50 | G5: 49 | H5: 49 | I5: 49 | J5: 46 | K5: 54 | L5: 52 | M5: 52 | N5: 53 | O5: 49 | P5: 50 | Q5: 52 | R5: 46 | S5: 46 | T5: 54 | U5: 50 | V5: 43 | W5: 49 | X5: 50 | Y5: 51 | Z5: 51 | AA5: 55 | AB5: 47 | AC5: 50 | AD5: 47 | AE5: 50 | AF5: 46 | AG5: 45 | AH5: 51 | AI5: 52 | AJ5: 47 | AK5: 47 | AL5: 47 | AM5: 45 | AN5: 51 | AO5: 50 | AP5: 47 | AQ5: 49 | AR5: 48 | AS5: 50 | AT5: 47 | AU5: 44 | AV5: 47 | AW5: 51 | AX5: 52 | AY5: 60 | AZ5: 50 | BA5: 45 | BB5: 50 | BC5: 53 | BD5: 48 | BE5: 53 | BF5: 52 | BG5: 46 | BH5: 51 | BI5: 47 | BJ5: 47 | BK5: 48 | BL5: 47
A6: U13 | B6: 1578 | C6: 226.47022 | D6: 143.51725 | E6: 28 | F6: 21 | G6: 21 | H6: 20 | I6: 16 | J6: 32 | K6: 25 | L6: 23 | M6: 24 | N6: 29 | O6: 27 | P6: 14 | Q6: 23 | R6: 25 | S6: 29 | T6: 20 | U6: 29 | V6: 25 | W6: 35 | X6: 31 | Y6: 22 | Z6: 34 | AA6: 30 | AB6: 30 | AC6: 29 | AD6: 31 | AE6: 32 | AF6: 22 | AG6: 25 | AH6: 24 | AI6: 28 | AJ6: 24 | AK6: 25 | AL6: 16 | AM6: 37 | AN6: 26 | AO6: 33 | AP6: 24 | AQ6: 25 | AR6: 29 | AS6: 24 | AT6: 26 | AU6: 20 | AV6: 28 | AW6: 25 | AX6: 28 | AY6: 33 | AZ6: 19 | BA6: 31 | BB6: 35 | BC6: 26 | BD6: 32 | BE6: 34 | BF6: 25 | BG6: 29 | BH6: 20 | BI6: 25 | BJ6: 26 | BK6: 24 | BL6: 25
A7: U14 | B7: 2467 | C7: 383.58936 | D7: 155.48819 | E7: 42 | F7: 38 | G7: 40 | H7: 39 | I7: 48 | J7: 32 | K7: 48 | L7: 45 | M7: 41 | N7: 40 | O7: 42 | P7: 29 | Q7: 43 | R7: 44 | S7: 39 | T7: 50 | U7: 44 | V7: 47 | W7: 41 | X7: 42 | Y7: 36 | Z7: 21 | AA7: 37 | AB7: 44 | AC7: 41 | AD7: 40 | AE7: 42 | AF7: 43 | AG7: 45 | AH7: 40 | AI7: 47 | AJ7: 41 | AK7: 31 | AL7: 43 | AM7: 41 | AN7: 39 | AO7: 38 | AP7: 41 | AQ7: 45 | AR7: 37 | AS7: 36 | AT7: 47 | AU7: 47 | AV7: 44 | AW7: 39 | AX7: 45 | AY7: 45 | AZ7: 37 | BA7: 34 | BB7: 44 | BC7: 40 | BD7: 41 | BE7: 42 | BF7: 44 | BG7: 43 | BH7: 42 | BI7: 44 | BJ7: 38 | BK7: 50 | BL7: 39
A8: U15 | B8: 2961 | C8: 489.15192 | D8: 165.19822 | E8: 53 | F8: 50 | G8: 52 | H8: 47 | I8: 50 | J8: 47 | K8: 39 | L8: 52 | M8: 37 | N8: 46 | O8: 51 | P8: 52 | Q8: 52 | R8: 44 | S8: 55 | T8: 50 | U8: 47 | V8: 51 | W8: 55 | X8: 48 | Y8: 48 | Z8: 48 | AA8: 51 | AB8: 49 | AC8: 49 | AD8: 53 | AE8: 49 | AF8: 54 | AG8: 52 | AH8: 51 | AI8: 52 | AJ8: 45 | AK8: 49 | AL8: 45 | AM8: 49 | AN8: 52 | AO8: 47 | AP8: 49 | AQ8: 52 | AR8: 51 | AS8: 47 | AT8: 50 | AU8: 54 | AV8: 51 | AW8: 49 | AX8: 48 | AY8: 47 | AZ8: 54 | BA8: 50 | BB8: 47 | BC8: 50 | BD8: 51 | BE8: 51 | BF8: 47 | BG8: 47 | BH8: 50 | BI8: 54 | BJ8: 44 | BK8: 52 | BL8: 45
A9: U16 | B9: 1524 | C9: 253.56685 | D9: 166.38245 | E9: 48 | F9: 38 | G9: 27 | H9: 36 | I9: 43 | J9: 40 | K9: 33 | L9: 36 | M9: 35 | N9: 39 | O9: 25 | P9: 43 | Q9: 52 | R9: 43 | S9: 36 | T9: 46 | U9: 47 | V9: 45 | W9: 48 | X9: 23 | Y9: 51 | Z9: 33 | AA9: 37 | AB9: 46 | AC9: 32 | AD9: 37 | AE9: 43 | AF9: 45 | AG9: 41 | AH9: 27 | AI9: 21 | AJ9: 34 | AK9: 41 | AL9: 33 | AM9: 29 | AN9: 35 | AO9: 23 | AP9: 5 | AQ9: 2 | AR9: 0 | AS9: 13 | AT9: 0 | AU9: 2 | AV9: 1 | AW9: 6 | AX9: 25 | AY9: 27 | AZ9: 7 | BA9: 25 | BB9: 0 | BC9: 1 | BD9: 2 | BE9: 2 | BF9: 5 | BG9: 9 | BH9: 0 | BI9: 0 | BJ9: 1 | BK9: 0 | BL9: 0
A10: U17 | B10: 3196 | C10: 490.49515 | D10: 153.47157 | E10: 52 | F10: 54 | G10: 56 | H10: 53 | I10: 51 | J10: 50 | K10: 52 | L10: 48 | M10: 50 | N10: 54 | O10: 54 | P10: 60 | Q10: 56 | R10: 56 | S10: 51 | T10: 50 | U10: 54 | V10: 51 | W10: 56 | X10: 58 | Y10: 55 | Z10: 60 | AA10: 55 | AB10: 42 | AC10: 50 | AD10: 52 | AE10: 49 | AF10: 56 | AG10: 58 | AH10: 55 | AI10: 62 | AJ10: 50 | AK10: 49 | AL10: 44 | AM10: 55 | AN10: 53 | AO10: 58 | AP10: 53 | AQ10: 51 | AR10: 50 | AS10: 54 | AT10: 59 | AU10: 51 | AV10: 54 | AW10: 50 | AX10: 55 | AY10: 56 | AZ10: 53 | BA10: 51 | BB10: 51 | BC10: 55 | BD10: 54 | BE10: 55 | BF10: 53 | BG10: 58 | BH10: 50 | BI10: 55 | BJ10: 50 | BK10: 53 | BL10: 56
A11: U18 | B11: 2653 | C11: 454.86216 | D11: 171.452 | E11: 37 | F11: 43 | G11: 40 | H11: 42 | I11: 50 | J11: 44 | K11: 48 | L11: 38 | M11: 50 | N11: 43 | O11: 48 | P11: 42 | Q11: 45 | R11: 46 | S11: 45 | T11: 45 | U11: 47 | V11: 43 | W11: 46 | X11: 47 | Y11: 40 | Z11: 45 | AA11: 47 | AB11: 45 | AC11: 45 | AD11: 42 | AE11: 47 | AF11: 42 | AG11: 42 | AH11: 49 | AI11: 41 | AJ11: 43 | AK11: 45 | AL11: 37 | AM11: 34 | AN11: 49 | AO11: 46 | AP11: 45 | AQ11: 47 | AR11: 45 | AS11: 42 | AT11: 48 | AU11: 40 | AV11: 47 | AW11: 38 | AX11: 47 | AY11: 51 | AZ11: 47 | BA11: 44 | BB11: 43 | BC11: 47 | BD11: 48 | BE11: 46 | BF11: 44 | BG11: 43 | BH11: 44 | BI11: 45 | BJ11: 39 | BK11: 42 | BL11: 43
A12: U19 | B12: 2460 | C12: 420.4878 | D12: 170.93 | E12: 44 | F12: 44 | G12: 39 | H12: 29 | I12: 42 | J12: 34 | K12: 43 | L12: 41 | M12: 41 | N12: 26 | O12: 42 | P12: 22 | Q12: 34 | R12: 40 | S12: 44 | T12: 39 | U12: 46 | V12: 40 | W12: 38 | X12: 43 | Y12: 39 | Z12: 48 | AA12: 42 | AB12: 43 | AC12: 45 | AD12: 42 | AE12: 45 | AF12: 48 | AG12: 43 | AH12: 36 | AI12: 49 | AJ12: 42 | AK12: 46 | AL12: 43 | AM12: 47 | AN12: 45 | AO12: 44 | AP12: 44 | AQ12: 41 | AR12: 34 | AS12: 45 | AT12: 40 | AU12: 42 | AV12: 43 | AW12: 46 | AX12: 46 | AY12: 46 | AZ12: 41 | BA12: 47 | BB12: 39 | BC12: 39 | BD12: 41 | BE12: 37 | BF12: 39 | BG12: 51 | BH12: 42 | BI12: 34 | BJ12: 32 | BK12: 39 | BL12: 34
A13: U2 | B13: 2772 | C13: 507.17576 | D13: 182.96384 | E13: 47 | F13: 48 | G13: 47 | H13: 46 | I13: 50 | J13: 45 | K13: 47 | L13: 46 | M13: 43 | N13: 45 | O13: 45 | P13: 44 | Q13: 49 | R13: 48 | S13: 48 | T13: 43 | U13: 50 | V13: 47 | W13: 47 | X13: 50 | Y13: 44 | Z13: 46 | AA13: 45 | AB13: 46 | AC13: 48 | AD13: 46 | AE13: 48 | AF13: 44 | AG13: 44 | AH13: 45 | AI13: 51 | AJ13: 46 | AK13: 46 | AL13: 43 | AM13: 46 | AN13: 44 | AO13: 45 | AP13: 46 | AQ13: 47 | AR13: 44 | AS13: 45 | AT13: 46 | AU13: 49 | AV13: 50 | AW13: 45 | AX13: 47 | AY13: 50 | AZ13: 45 | BA13: 48 | BB13: 43 | BC13: 46 | BD13: 48 | BE13: 44 | BF13: 49 | BG13: 44 | BH13: 44 | BI13: 45 | BJ13: 45 | BK13: 45 | BL13: 45
... A39: U9 | B39: 2752 | C39: 410.72035 | D39: 149.24431 | E39: 42 | F39: 36 | G39: 41 | H39: 52 | I39: 45 | J39: 43 | K39: 42 | L39: 40 | M39: 38 | N39: 41 | O39: 43 | P39: 49 | Q39: 49 | R39: 44 | S39: 46 | T39: 38 | U39: 48 | V39: 40 | W39: 55 | X39: 55 | Y39: 48 | Z39: 52 | AA39: 51 | AB39: 51 | AC39: 49 | AD39: 50 | AE39: 44 | AF39: 41 | AG39: 48 | AH39: 52 | AI39: 52 | AJ39: 40 | AK39: 49 | AL39: 49 | AM39: 46 | AN39: 49 | AO39: 46 | AP39: 50 | AQ39: 43 | AR39: 50 | AS39: 43 | AT39: 46 | AU39: 43 | AV39: 42 | AW39: 40 | AX39: 43 | AY39: 48 | AZ39: 46 | BA39: 47 | BB39: 53 | BC39: 49 | BD39: 47 | BE39: 50 | BF39: 42 | BG39: 43 | BH39: 45 | BI39: 47 | BJ39: 44 | BK39: 47 | BL39: 40
A41: Total | B41: =SUM(B2:B39) -> 95471 | D41: Total | E41: =SUM(E2:E39) -> 1645 | F41: =SUM(F2:F39) -> 1635 | G41: =SUM(G2:G39) -> 1634 | H41: =SUM(H2:H39) -> 1617 | I41: =SUM(I2:I39) -> 1625 | J41: =SUM(J2:J39) -> 1570 | K41: =SUM(K2:K39) -> 1660 | L41: =SUM(L2:L39) -> 1580 | ... BL41: =SUM(BL2:BL39) -> 1534
A42: Promedio | B42: =AVERAGE(B2:B39) -> 2512.3947 | D42: Minimo | E42: =MIN(E2:E39) -> 0 | F42: =MIN(F2:F39) -> 0 | G42: =MIN(G2:G39) -> 0 | H42: =MIN(H2:H39) -> 0 | I42: =MIN(I2:I39) -> 0 | J42: =MIN(J2:J39) -> 0 | K42: =MIN(K2:K39) -> 0 | L42: =MIN(L2:L39) -> 0 | ... BL42: =MIN(BL2:BL39) -> 0
B43: Total | C43: =SUM(C2:C39)-C4 -> 15588.167 | D43: Maximo | E43: =MAX(E2:E39) -> 55 | F43: =MAX(F2:F39) -> 58 | G43: =MAX(G2:G39) -> 56 | H43: =MAX(H2:H39) -> 57 | I43: =MAX(I2:I39) -> 55 | J43: =MAX(J2:J39) -> 54 | K43: =MAX(K2:K39) -> 55 | L43: =MAX(L2:L39) -> 52 | ... BL43: =MAX(BL2:BL39) -> 57
D44: Mediana | E44: =MEDIAN(E2:E39) -> 44.5 | F44: =MEDIAN(F2:F39) -> 46 | G44: =MEDIAN(G2:G39) -> 45 | H44: =MEDIAN(H2:H39) -> 45 | I44: =MEDIAN(I2:I39) -> 45.5 | J44: =MEDIAN(J2:J39) -> 45 | K44: =MEDIAN(K2:K39) -> 48 | L44: =MEDIAN(L2:L39) -> 46 | ... BL44: =MEDIAN(BL2:BL39) -> 45
D45: Promedio | E45: =AVERAGE(E2:E39) -> 43.289474 | F45: =AVERAGE(F2:F39) -> 43.026316 | G45: =AVERAGE(G2:G39) -> 43 | H45: =AVERAGE(H2:H39) -> 42.552632 | I45: =AVERAGE(I2:I39) -> 42.763158 | J45: =AVERAGE(J2:J39) -> 41.315789 | K45: =AVERAGE(K2:K39) -> 43.684211 | L45: =AVERAGE(L2:L39) -> 41.578947 | ... BL45: =AVERAGE(BL2:BL39) -> 40.368421

Sheet Summary
A1: Metric | B1: Value
A2: Participants | B2: 38 | D2: Imagen | E2: Total | F2: Minimo | G2: Maximo | H2: Mediana | I2: Promedio | K2: Imagen | L2: U1 | M2: U10 | N2: U11 | O2: U12 | P2: U13 | Q2: U14 | R2: U15 | S2: U16 | T2: U17 | U2: U18 | V2: U19 | W2: U2 | X2: U20 | Y2: U21 | Z2: U22 | AA2: U23 | AB2: U24 | AC2: U25 | AD2: U26 | AE2: U27 | AF2: U28 | AG2: U29 | AH2: U3 | AI2: U30 | AJ2: U31 | AK2: U32 | AL2: U33 | AM2: U34 | AN2: U35 | AO2: U36 | AP2: U37 | AQ2: U38 | AR2: U4 | AS2: U5 | AT2: U6 | AU2: U7 | AV2: U8 | AW2: U9 | AX2: Total
A3: Average Fixations | B3: 2512.39 | D3: 1 | E3: 1645 | F3: 0 | G3: 55 | H3: 44.5 | I3: 43.289474 | K3: 1 | L3: 51 | M3: 43 | N3: 0 | O3: 47 | P3: 28 | Q3: 42 | R3: 53 | S3: 48 | T3: 52 | U3: 37 | V3: 44 | W3: 47 | X3: 44 | Y3: 51 | Z3: 47 | AA3: 39 | AB3: 55 | AC3: 29 | AD3: 47 | AE3: 42 | AF3: 43 | AG3: 43 | AH3: 48 | AI3: 43 | AJ3: 44 | AK3: 42 | AL3: 50 | AM3: 45 | AN3: 48 | AO3: 32 | AP3: 45 | AQ3: 46 | AR3: 43 | AS3: 49 | AT3: 49 | AU3: 42 | AV3: 45 | AW3: 42 | AX3: =SUM(L3:AW3) -> 1645
A4: Average Fixation Duration (s) | B4: =AVERAGE(Participants!D2:D39) -> 163.58573 | D4: 2 | E4: 1635 | F4: 0 | G4: 58 | H4: 46 | I4: 43.026316 | K4: 2 | L4: 58 | M4: 46 | N4: 0 | O4: 50 | P4: 21 | Q4: 38 | R4: 50 | S4: 38 | T4: 54 | U4: 43 | V4: 44 | W4: 48 | X4: 42 | Y4: 51 | Z4: 49 | AA4: 45 | AB4: 49 | AC4: 45 | AD4: 46 | AE4: 40 | AF4: 39 | AG4: 46 | AH4: 56 | AI4: 40 | AJ4: 38 | AK4: 49 | AL4: 50 | AM4: 46 | AN4: 46 | AO4: 44 | AP4: 49 | AQ4: 27 | AR4: 55 | AS4: 40 | AT4: 48 | AU4: 23 | AV4: 46 | AW4: 36 | AX4: =SUM(L4:AW4) -> 1635
A5: Fewest Fixations | B5: U11 (279) | D5: 3 | E5: 1634 | F5: 0 | G5: 56 | H5: 45 | I5: 43 | K5: 3 | L5: 56 | M5: 43 | N5: 0 | O5: 49 | P5: 21 | Q5: 40 | R5: 52 | S5: 27 | T5: 56 | U5: 40 | V5: 39 | W5: 47 | X5: 44 | Y5: 50 | Z5: 47 | AA5: 49 | AB5: 50 | AC5: 43 | AD5: 45 | AE5: 39 | AF5: 45 | AG5: 30 | AH5: 48 | AI5: 45 | AJ5: 53 | AK5: 43 | AL5: 53 | AM5: 42 | AN5: 52 | AO5: 48 | AP5: 39 | AQ5: 28 | AR5: 49 | AS5: 42 | AT5: 47 | AU5: 40 | AV5: 52 | AW5: 41 | AX5: =SUM(L5:AW5) -> 1634
A6: Most Fixations | B6: U17 (3196) | D6: 4 | E6: 1617 | F6: 0 | G6: 57 | H6: 45 | I6: 42.552632 | K6: 4 | L6: 51 | M6: 43 | N6: 0 | O6: 49 | P6: 20 | Q6: 39 | R6: 47 | S6: 36 | T6: 53 | U6: 42 | V6: 29 | W6: 46 | X6: 45 | Y6: 47 | Z6: 47 | AA6: 43 | AB6: 52 | AC6: 43 | AD6: 45 | AE6: 40 | AF6: 47 | AG6: 48 | AH6: 50 | AI6: 39 | AJ6: 47 | AK6: 45 | AL6: 57 | AM6: 42 | AN6: 48 | AO6: 37 | AP6: 45 | AQ6: 10 | AR6: 45 | AS6: 48 | AT6: 45 | AU6: 46 | AV6: 49 | AW6: 52 | AX6: =SUM(L6:AW6) -> 1617
A7: Longest Total Fixation Duration | B7: U35 (516.83 s) | D7: 5 | E7: 1625 | F7: 0 | G7: 55 | H7: 45.5 | I7: 42.763158 | K7: 5 | L7: 44 | M7: 40 | N7: 0 | O7: 49 | P7: 16 | Q7: 48 | R7: 50 | S7: 43 | T7: 51 | U7: 50 | V7: 42 | W7: 50 | X7: 44 | Y7: 55 | Z7: 48 | AA7: 46 | AB7: 52 | AC7: 37 | AD7: 44 | AE7: 43 | AF7: 41 | AG7: 37 | AH7: 51 | AI7: 45 | AJ7: 48 | AK7: 46 | AL7: 37 | AM7: 48 | AN7: 48 | AO7: 45 | AP7: 54 | AQ7: 6 | AR7: 51 | AS7: 42 | AT7: 47 | AU7: 35 | AV7: 47 | AW7: 45 | AX7: =SUM(L7:AW7) -> 1625
A8: Total Fixations | B8: 94573 | D8: 6 | E8: 1570 | F8: 0 | G8: 54 | H8: 45 | I8: 41.315789 | K8: 6 | L8: 53 | M8: 39 | N8: 0 | O8: 46 | P8: 32 | Q8: 32 | R8: 47 | S8: 40 | T8: 50 | U8: 44 | V8: 34 | W8: 45 | X8: 45 | Y8: 48 | Z8: 45 | AA8: 46 | AB8: 46 | AC8: 36 | AD8: 46 | AE8: 38 | AF8: 37 | AG8: 34 | AH8: 46 | AI8: 37 | AJ8: 50 | AK8: 40 | AL8: 49 | AM8: 45 | AN8: 49 | AO8: 47 | AP8: 52 | AQ8: 1 | AR8: 54 | AS8: 39 | AT8: 50 | AU8: 41 | AV8: 44 | AW8: 43 | AX8: =SUM(L8:AW8) -> 1570
D9: 7 | E9: 1660 | F9: 0 | G9: 55 | H9: 48 | I9: 43.684211 | K9: 7 | L9: 55 | M9: 49 | N9: 0 | O9: 54 | P9: 25 | Q9: 48 | R9: 39 | S9: 33 | T9: 52 | U9: 48 | V9: 43 | W9: 47 | X9: 48 | Y9: 51 | Z9: 54 | AA9: 45 | AB9: 47 | AC9: 13 | AD9: 44 | AE9: 47 | AF9: 48 | AG9: 49 | AH9: 43 | AI9: 48 | AJ9: 49 | AK9: 48 | AL9: 53 | AM9: 50 | AN9: 48 | AO9: 44 | AP9: 51 | AQ9: 12 | AR9: 49 | AS9: 48 | AT9: 53 | AU9: 42 | AV9: 41 | AW9: 42 | AX9: =SUM(L9:AW9) -> 1660
D10: 8 | E10: 1580 | F10: 0 | G10: 52 | H10: 46 | I10: 41.578947 | K10: 8 | L10: 52 | M10: 36 | N10: 0 | O10: 52 | P10: 23 | Q10: 45 | R10: 52 | S10: 36 | T10: 48 | U10: 38 | V10: 41 | W10: 46 | X10: 46 | Y10: 47 | Z10: 46 | AA10: 49 | AB10: 48 | AC10: 8 | AD10: 47 | AE10: 42 | AF10: 46 | AG10: 50 | AH10: 47 | AI10: 49 | AJ10: 45 | AK10: 38 | AL10: 49 | AM10: 47 | AN10: 43 | AO10: 47 | AP10: 42 | AQ10: 4 | AR10: 49 | AS10: 47 | AT10: 50 | AU10: 40 | AV10: 45 | AW10: 40 | AX10: =SUM(L10:AW10) -> 1580
D11: 9 | E11: 1574 | F11: 0 | G11: 53 | H11: 44 | I11: 41.421053 | K11: 9 | L11: 49 | M11: 40 | N11: 0 | O11: 52 | P11: 24 | Q11: 41 | R11: 37 | S11: 35 | T11: 50 | U11: 50 | V11: 41 | W11: 43 | X11: 44 | Y11: 51 | Z11: 49 | AA11: 40 | AB11: 52 | AC11: 18 | AD11: 49 | AE11: 42 | AF11: 44 | AG11: 44 | AH11: 49 | AI11: 47 | AJ11: 48 | AK11: 44 | AL11: 47 | AM11: 43 | AN11: 47 | AO11: 48 | AP11: 48 | AQ11: 13 | AR11: 46 | AS11: 45 | AT11: 53 | AU11: 20 | AV11: 43 | AW11: 38 | AX11: =SUM(L11:AW11) -> 1574
D12: 10 | E12: 1585 | F12: 0 | G12: 56 | H12: 44 | I12: 41.710526 | K12: 10 | L12: 56 | M12: 37 | N12: 0 | O12: 53 | P12: 29 | Q12: 40 | R12: 46 | S12: 39 | T12: 54 | U12: 43 | V12: 26 | W12: 45 | X12: 48 | Y12: 45 | Z12: 44 | AA12: 45 | AB12: 51 | AC12: 5 | AD12: 40 | AE12: 43 | AF12: 42 | AG12: 40 | AH12: 47 | AI12: 45 | AJ12: 47 | AK12: 52 | AL12: 52 | AM12: 43 | AN12: 49 | AO12: 46 | AP12: 43 | AQ12: 31 | AR12: 53 | AS12: 48 | AT12: 44 | AU12: 34 | AV12: 39 | AW12: 41 | AX12: =SUM(L12:AW12) -> 1585
D13: 11 | E13: 1642 | F13: 0 | G13: 54 | H13: 46.5 | I13: 43.210526 | K13: 11 | L13: 49 | M13: 42 | N13: 0 | O13: 49 | P13: 27 | Q13: 42 | R13: 51 | S13: 25 | T13: 54 | U13: 48 | V13: 42 | W13: 45 | X13: 41 | Y13: 48 | Z13: 51 | AA13: 44 | AB13: 49 | AC13: 7 | AD13: 45 | AE13: 46 | AF13: 47 | AG13: 53 | AH13: 51 | AI13: 49 | AJ13: 46 | AK13: 47 | AL13: 52 | AM13: 50 | AN13: 45 | AO13: 47 | AP13: 48 | AQ13: 39 | AR13: 47 | AS13: 46 | AT13: 50 | AU13: 36 | AV13: 41 | AW13: 43 | AX13: =SUM(L13:AW13) -> 1642
D14: 12 | E14: 1614 | F14: 0 | G14: 60 | H14: 44.5 | I14: 42.473684 | K14: 12 | L14: 54 | M14: 42 | N14: 0 | O14: 50 | P14: 14 | Q14: 29 | R14: 52 | S14: 43 | T14: 60 | U14: 42 | V14: 22 | W14: 44 | X14: 42 | Y14: 49 | Z14: 52 | AA14: 44 | AB14: 45 | AC14: 13 | AD14: 47 | AE14: 40 | AF14: 41 | AG14: 44 | AH14: 47 | AI14: 44 | AJ14: 50 | AK14: 48 | AL14: 45 | AM14: 42 | AN14: 44 | AO14: 50 | AP14: 48 | AQ14: 41 | AR14: 46 | AS14: 52 | AT14: 48 | AU14: 42 | AV14: 49 | AW14: 49 | AX14: =SUM(L14:AW14) -> 1614
D15: 13 | E15: 1697 | F15: 0 | G15: 56 | H15: 48.5 | I15: 44.657895 | K15: 13 | L15: 43 | M15: 39 | N15: 0 | O15: 52 | P15: 23 | Q15: 43 | R15: 52 | S15: 52 | T15: 56 | U15: 45 | V15: 34 | W15: 49 | X15: 44 | Y15: 51 | Z15: 51 | AA15: 50 | AB15: 52 | AC15: 7 | AD15: 52 | AE15: 43 | AF15: 48 | AG15: 44 | AH15: 51 | AI15: 48 | AJ15: 56 | AK15: 54 | AL15: 51 | AM15: 45 | AN15: 48 | AO15: 52 | AP15: 51 | AQ15: 35 | AR15: 51 | AS15: 45 | AT15: 51 | AU15: 35 | AV15: 45 | AW15: 49 | AX15: =SUM(L15:AW15) -> 1697
D16: 14 | E16: 1625 | F16: 11 | G16: 56 | H16: 44 | I16: 42.763158 | K16: 14 | L16: 52 | M16: 29 | N16: 38 | O16: 46 | P16: 25 | Q16: 44 | R16: 44 | S16: 43 | T16: 56 | U16: 46 | V16: 40 | W16: 48 | X16: 41 | Y16: 47 | Z16: 50 | AA16: 45 | AB16: 46 | AC16: 11 | AD16: 45 | AE16: 48 | AF16: 44 | AG16: 35 | AH16: 48 | AI16: 41 | AJ16: 44 | AK16: 45 | AL16: 50 | AM16: 39 | AN16: 47 | AO16: 47 | AP16: 44 | AQ16: 41 | AR16: 49 | AS16: 45 | AT16: 40 | AU16: 38 | AV16: 40 | AW16: 44 | AX16: =SUM(L16:AW16) -> 1625
D17: 15 | E17: 1649 | F17: 7 | G17: 55 | H17: 45.5 | I17: 43.394737 | K17: 15 | L17: 53 | M17: 41 | N17: 7 | O17: 46 | P17: 29 | Q17: 39 | R17: 55 | S17: 36 | T17: 51 | U17: 45 | V17: 44 | W17: 48 | X17: 41 | Y17: 48 | Z17: 53 | AA17: 43 | AB17: 53 | AC17: 17 | AD17: 46 | AE17: 41 | AF17: 39 | AG17: 46 | AH17: 44 | AI17: 53 | AJ17: 43 | AK17: 47 | AL17: 51 | AM17: 43 | AN17: 50 | AO17: 50 | AP17: 47 | AQ17: 23 | AR17: 52 | AS17: 43 | AT17: 48 | AU17: 43 | AV17: 45 | AW17: 46 | AX17: =SUM(L17:AW17) -> 1649
D18: 16 | E18: 1633 | F18: 6 | G18: 56 | H18: 46 | I18: 42.973684 | K18: 16 | L18: 48 | M18: 41 | N18: 6 | O18: 54 | P18: 20 | Q18: 50 | R18: 50 | S18: 46 | T18: 50 | U18: 45 | V18: 39 | W18: 43 | X18: 46 | Y18: 47 | Z18: 56 | AA18: 37 | AB18: 51 | AC18: 7 | AD18: 42 | AE18: 41 | AF18: 42 | AG18: 43 | AH18: 52 | AI18: 48 | AJ18: 46 | AK18: 43 | AL18: 55 | AM18: 41 | AN18: 51 | AO18: 49 | AP18: 48 | AQ18: 30 | AR18: 45 | AS18: 49 | AT18: 46 | AU18: 47 | AV18: 41 | AW18: 38 | AX18: =SUM(L18:AW18) -> 1633
D19: 17 | E19: 1689 | F19: 1 | G19: 56 | H19: 47 | I19: 44.447368 | K19: 17 | L19: 56 | M19: 41 | N19: 1 | O19: 50 | P19: 29 | Q19: 44 | R19: 47 | S19: 47 | T19: 54 | U19: 47 | V19: 46 | W19: 50 | X19: 43 | Y19: 50 | Z19: 55 | AA19: 33 | AB19: 54 | AC19: 2 | AD19: 45 | AE19: 48 | AF19: 50 | AG19: 49 | AH19: 50 | AI19: 48 | AJ19: 47 | AK19: 46 | AL19: 49 | AM19: 46 | AN19: 46 | AO19: 53 | AP19: 49 | AQ19: 31 | AR19: 48 | AS19: 49 | AT19: 47 | AU19: 44 | AV19: 47 | AW19: 48 | AX19: =SUM(L19:AW19) -> 1689
D20: 18 | E20: 1599 | F20: 7 | G20: 56 | H20: 44.5 | I20: 42.078947 | K20: 18 | L20: 56 | M20: 45 | N20: 13 | O20: 43 | P20: 25 | Q20: 47 | R20: 51 | S20: 45 | T20: 51 | U20: 43 | V20: 40 | W20: 47 | X20: 24 | Y20: 43 | Z20: 50 | AA20: 23 | AB20: 47 | AC20: 7 | AD20: 51 | AE20: 43 | AF20: 44 | AG20: 39 | AH20: 45 | AI20: 40 | AJ20: 51 | AK20: 42 | AL20: 50 | AM20: 42 | AN20: 48 | AO20: 43 | AP20: 39 | AQ20: 38 | AR20: 50 | AS20: 51 | AT20: 49 | AU20: 47 | AV20: 47 | AW20: 40 | AX20: =SUM(L20:AW20) -> 1599
... D62: 60 | E62: 1534 | F62: 0 | G62: 57 | H62: 45 | I62: 40.368421 | K62: 60 | L62: 57 | M62: 36 | N62: 0 | O62: 47 | P62: 25 | Q62: 39 | R62: 45 | S62: 0 | T62: 56 | U62: 43 | V62: 34 | W62: 45 | X62: 42 | Y62: 48 | Z62: 48 | AA62: 0 | AB62: 52 | AC62: 49 | AD62: 49 | AE62: 44 | AF62: 42 | AG62: 35 | AH62: 46 | AI62: 49 | AJ62: 52 | AK62: 35 | AL62: 55 | AM62: 45 | AN62: 50 | AO62: 47 | AP62: 39 | AQ62: 0 | AR62: 46 | AS62: 50 | AT62: 47 | AU62: 53 | AV62: 44 | AW62: 40 | AX62: =SUM(L62:AW62) -> 1534
D64: Total | E64: =SUM(E3:E62) -> 95471
K65: max | L65: =MAX(Summary!$L$3:$L$62) -> 61 | M65: =MAX(Summary!$M$3:$M$62) -> 52 | N65: =MAX(Summary!$N$3:$N$62) -> 38 | O65: =MAX(Summary!$O$3:$O$62) -> 60 | P65: =MAX(Summary!$P$3:$P$62) -> 37 | Q65: =MAX(Summary!$Q$3:$Q$62) -> 50 | R65: =MAX(Summary!$R$3:$R$62) -> 55 | S65: =MAX(Summary!$S$3:$S$62) -> 52 | T65: =MAX(Summary!$T$3:$T$62) -> 62 | U65: =MAX(Summary!$U$3:$U$62) -> 51 | V65: =MAX(Summary!$V$3:$V$62) -> 51 | W65: =MAX(Summary!$W$3:$W$62) -> 51 | X65: =MAX(Summary!$X$3:$X$62) -> 50 | Y65: =MAX(Summary!$Y$3:$Y$62) -> 55 | Z65: =MAX(Summary!$Z$3:$Z$62) -> 58 | AA65: =MAX(Summary!$AA$3:$AA$62) -> 50 | AB65: =MAX(Summary!$AB$3:$AB$62) -> 59 | AC65: =MAX(Summary!$AC$3:$AC$62) -> 50 | AD65: =MAX(Summary!$AD$3:$AD$62) -> 55 | AE65: =MAX(Summary!$AE$3:$AE$62) -> 50 | AF65: =MAX(Summary!$AF$3:$AF$62) -> 53 | AG65: =MAX(Summary!$AG$3:$AG$62) -> 54 | AH65: =MAX(Summary!$AH$3:$AH$62) -> 57 | AI65: =MAX(Summary!$AI$3:$AI$62) -> 59 | AJ65: =MAX(Summary!$AJ$3:$AJ$62) -> 56 | AK65: =MAX(Summary!$AK$3:$AK$62) -> 56 | AL65: =MAX(Summary!$AL$3:$AL$62) -> 62 | AM65: =MAX(Summary!$AM$3:$AM$62) -> 51 | AN65: =MAX(Summary!$AN$3:$AN$62) -> 56 | AO65: =MAX(Summary!$AO$3:$AO$62) -> 54 | AP65: =MAX(Summary!$AP$3:$AP$62) -> 54 | AQ65: =MAX(Summary!$AQ$3:$AQ$62) -> 50 | AR65: =MAX(Summary!$AR$3:$AR$62) -> 57 | AS65: =MAX(Summary!$AS$3:$AS$62) -> 57 | AT65: =MAX(Summary!$AT$3:$AT$62) -> 57 | AU65: =MAX(Summary!$AU$3:$AU$62) -> 54 | AV65: =MAX(Summary!$AV$3:$AV$62) -> 52 | AW65: =MAX(Summary!$AW$3:$AW$62) -> 55
K66: min | L66: =MIN(Summary!$L$3:$L$62) -> 42 | M66: =MIN(Summary!$M$3:$M$62) -> 0 | N66: =MIN(Summary!$N$3:$N$62) -> 0 | O66: =MIN(Summary!$O$3:$O$62) -> 43 | P66: =MIN(Summary!$P$3:$P$62) -> 14 | Q66: =MIN(Summary!$Q$3:$Q$62) -> 21 | R66: =MIN(Summary!$R$3:$R$62) -> 37 | S66: =MIN(Summary!$S$3:$S$62) -> 0 | T66: =MIN(Summary!$T$3:$T$62) -> 42 | U66: =MIN(Summary!$U$3:$U$62) -> 34 | V66: =MIN(Summary!$V$3:$V$62) -> 22 | W66: =MIN(Summary!$W$3:$W$62) -> 43 | X66: =MIN(Summary!$X$3:$X$62) -> 24 | Y66: =MIN(Summary!$Y$3:$Y$62) -> 43 | Z66: =MIN(Summary!$Z$3:$Z$62) -> 40 | AA66: =MIN(Summary!$AA$3:$AA$62) -> 0 | AB66: =MIN(Summary!$AB$3:$AB$62) -> 41 | AC66: =MIN(Summary!$AC$3:$AC$62) -> 0 | AD66: =MIN(Summary!$AD$3:$AD$62) -> 40 | AE66: =MIN(Summary!$AE$3:$AE$62) -> 38 | AF66: =MIN(Summary!$AF$3:$AF$62) -> 35 | AG66: =MIN(Summary!$AG$3:$AG$62) -> 20 | AH66: =MIN(Summary!$AH$3:$AH$62) -> 42 | AI66: =MIN(Summary!$AI$3:$AI$62) -> 35 | AJ66: =MIN(Summary!$AJ$3:$AJ$62) -> 38 | AK66: =MIN(Summary!$AK$3:$AK$62) -> 35 | AL66: =MIN(Summary!$AL$3:$AL$62) -> 37 | AM66: =MIN(Summary!$AM$3:$AM$62) -> 36 | AN66: =MIN(Summary!$AN$3:$AN$62) -> 43 | AO66: =MIN(Summary!$AO$3:$AO$62) -> 32 | AP66: =MIN(Summary!$AP$3:$AP$62) -> 35 | AQ66: =MIN(Summary!$AQ$3:$AQ$62) -> 0 | AR66: =MIN(Summary!$AR$3:$AR$62) -> 37 | AS66: =MIN(Summary!$AS$3:$AS$62) -> 38 | AT66: =MIN(Summary!$AT$3:$AT$62) -> 40 | AU66: =MIN(Summary!$AU$3:$AU$62) -> 20 | AV66: =MIN(Summary!$AV$3:$AV$62) -> 36 | AW66: =MIN(Summary!$AW$3:$AW$62) -> 36
K67: median | L67: =MEDIAN(Summary!$L$3:$L$62) -> 53 | M67: =MEDIAN(Summary!$M$3:$M$62) -> 40 | N67: =MEDIAN(Summary!$N$3:$N$62) -> 1 | O67: =MEDIAN(Summary!$O$3:$O$62) -> 49 | P67: =MEDIAN(Summary!$P$3:$P$62) -> 25.5 | Q67: =MEDIAN(Summary!$Q$3:$Q$62) -> 41.5 | R67: =MEDIAN(Summary!$R$3:$R$62) -> 50 | S67: =MEDIAN(Summary!$S$3:$S$62) -> 30.5 | T67: =MEDIAN(Summary!$T$3:$T$62) -> 53.5 | U67: =MEDIAN(Summary!$U$3:$U$62) -> 45 | V67: =MEDIAN(Summary!$V$3:$V$62) -> 42 | W67: =MEDIAN(Summary!$W$3:$W$62) -> 46 | X67: =MEDIAN(Summary!$X$3:$X$62) -> 43.5 | Y67: =MEDIAN(Summary!$Y$3:$Y$62) -> 48 | Z67: =MEDIAN(Summary!$Z$3:$Z$62) -> 50 | AA67: =MEDIAN(Summary!$AA$3:$AA$62) -> 0 | AB67: =MEDIAN(Summary!$AB$3:$AB$62) -> 50 | AC67: =MEDIAN(Summary!$AC$3:$AC$62) -> 11 | AD67: =MEDIAN(Summary!$AD$3:$AD$62) -> 47 | AE67: =MEDIAN(Summary!$AE$3:$AE$62) -> 42 | AF67: =MEDIAN(Summary!$AF$3:$AF$62) -> 44 | AG67: =MEDIAN(Summary!$AG$3:$AG$62) -> 44 | AH67: =MEDIAN(Summary!$AH$3:$AH$62) -> 48 | AI67: =MEDIAN(Summary!$AI$3:$AI$62) -> 46 | AJ67: =MEDIAN(Summary!$AJ$3:$AJ$62) -> 47.5 | AK67: =MEDIAN(Summary!$AK$3:$AK$62) -> 46 | AL67: =MEDIAN(Summary!$AL$3:$AL$62) -> 51 | AM67: =MEDIAN(Summary!$AM$3:$AM$62) -> 45 | AN67: =MEDIAN(Summary!$AN$3:$AN$62) -> 48 | AO67: =MEDIAN(Summary!$AO$3:$AO$62) -> 47 | AP67: =MEDIAN(Summary!$AP$3:$AP$62) -> 45 | AQ67: =MEDIAN(Summary!$AQ$3:$AQ$62) -> 29 | AR67: =MEDIAN(Summary!$AR$3:$AR$62) -> 49 | AS67: =MEDIAN(Summary!$AS$3:$AS$62) -> 46 | AT67: =MEDIAN(Summary!$AT$3:$AT$62) -> 49 | AU67: =MEDIAN(Summary!$AU$3:$AU$62) -> 41.5 | AV67: =MEDIAN(Summary!$AV$3:$AV$62) -> 45 | AW67: =MEDIAN(Summary!$AW$3:$AW$62) -> 46
K68: average | L68: =AVERAGE(Summary!$L$3:$L$62) -> 52.416667 | M68: =AVERAGE(Summary!$M$3:$M$62) -> 35.3 | N68: =AVERAGE(Summary!$N$3:$N$62) -> 4.65 | O68: =AVERAGE(Summary!$O$3:$O$62) -> 49.233333 | P68: =AVERAGE(Summary!$P$3:$P$62) -> 26.3 | Q68: =AVERAGE(Summary!$Q$3:$Q$62) -> 41.116667 | R68: =AVERAGE(Summary!$R$3:$R$62) -> 49.35 | S68: =AVERAGE(Summary!$S$3:$S$62) -> 25.4 | T68: =AVERAGE(Summary!$T$3:$T$62) -> 53.266667 | U68: =AVERAGE(Summary!$U$3:$U$62) -> 44.216667 | V68: =AVERAGE(Summary!$V$3:$V$62) -> 41 | W68: =AVERAGE(Summary!$W$3:$W$62) -> 46.2 | X68: =AVERAGE(Summary!$X$3:$X$62) -> 42.183333 | Y68: =AVERAGE(Summary!$Y$3:$Y$62) -> 48.583333 | Z68: =AVERAGE(Summary!$Z$3:$Z$62) -> 50.466667 | AA68: =AVERAGE(Summary!$AA$3:$AA$62) -> 13.283333 | AB68: =AVERAGE(Summary!$AB$3:$AB$62) -> 49.866667 | AC68: =AVERAGE(Summary!$AC$3:$AC$62) -> 18.3 | AD68: =AVERAGE(Summary!$AD$3:$AD$62) -> 47.1 | AE68: =AVERAGE(Summary!$AE$3:$AE$62) -> 42.55 | AF68: =AVERAGE(Summary!$AF$3:$AF$62) -> 44.416667 | AG68: =AVERAGE(Summary!$AG$3:$AG$62) -> 43.05 | AH68: =AVERAGE(Summary!$AH$3:$AH$62) -> 48.666667 | AI68: =AVERAGE(Summary!$AI$3:$AI$62) -> 45.983333 | AJ68: =AVERAGE(Summary!$AJ$3:$AJ$62) -> 47.55 | AK68: =AVERAGE(Summary!$AK$3:$AK$62) -> 45.566667 | AL68: =AVERAGE(Summary!$AL$3:$AL$62) -> 50.666667 | AM68: =AVERAGE(Summary!$AM$3:$AM$62) -> 44.633333 | AN68: =AVERAGE(Summary!$AN$3:$AN$62) -> 48.45 | AO68: =AVERAGE(Summary!$AO$3:$AO$62) -> 47.4 | AP68: =AVERAGE(Summary!$AP$3:$AP$62) -> 45.316667 | AQ68: =AVERAGE(Summary!$AQ$3:$AQ$62) -> 24.516667 | AR68: =AVERAGE(Summary!$AR$3:$AR$62) -> 48.966667 | AS68: =AVERAGE(Summary!$AS$3:$AS$62) -> 46.15 | AT68: =AVERAGE(Summary!$AT$3:$AT$62) -> 48.6 | AU68: =AVERAGE(Summary!$AU$3:$AU$62) -> 40.15 | AV68: =AVERAGE(Summary!$AV$3:$AV$62) -> 44.45 | AW68: =AVERAGE(Summary!$AW$3:$AW$62) -> 45.866667
L71: Imagenes vistas con mas de X fijaciones
K72: >20 | L72: =COUNTIF(Summary!$L$3:$L$62,">20") -> 60 | M72: =COUNTIF(Summary!$M$3:$M$62,">20") -> 52 | N72: =COUNTIF(Summary!$N$3:$N$62,">20") -> 4 | O72: =COUNTIF(Summary!$O$3:$O$62,">20") -> 60 | P72: =COUNTIF(Summary!$P$3:$P$62,">20") -> 52 | Q72: =COUNTIF(Summary!$Q$3:$Q$62,">20") -> 60 | R72: =COUNTIF(Summary!$R$3:$R$62,">20") -> 60 | S72: =COUNTIF(Summary!$S$3:$S$62,">20") -> 40 | T72: =COUNTIF(Summary!$T$3:$T$62,">20") -> 60 | U72: =COUNTIF(Summary!$U$3:$U$62,">20") -> 60 | V72: =COUNTIF(Summary!$V$3:$V$62,">20") -> 60 | W72: =COUNTIF(Summary!$W$3:$W$62,">20") -> 60 | X72: =COUNTIF(Summary!$X$3:$X$62,">20") -> 60 | Y72: =COUNTIF(Summary!$Y$3:$Y$62,">20") -> 60 | Z72: =COUNTIF(Summary!$Z$3:$Z$62,">20") -> 60 | AA72: =COUNTIF(Summary!$AA$3:$AA$62,">20") -> 19 | AB72: =COUNTIF(Summary!$AB$3:$AB$62,">20") -> 60 | AC72: =COUNTIF(Summary!$AC$3:$AC$62,">20") -> 21 | AD72: =COUNTIF(Summary!$AD$3:$AD$62,">20") -> 60 | AE72: =COUNTIF(Summary!$AE$3:$AE$62,">20") -> 60 | AF72: =COUNTIF(Summary!$AF$3:$AF$62,">20") -> 60 | AG72: =COUNTIF(Summary!$AG$3:$AG$62,">20") -> 59 | AH72: =COUNTIF(Summary!$AH$3:$AH$62,">20") -> 60 | AI72: =COUNTIF(Summary!$AI$3:$AI$62,">20") -> 60 | AJ72: =COUNTIF(Summary!$AJ$3:$AJ$62,">20") -> 60 | AK72: =COUNTIF(Summary!$AK$3:$AK$62,">20") -> 60 | AL72: =COUNTIF(Summary!$AL$3:$AL$62,">20") -> 60 | AM72: =COUNTIF(Summary!$AM$3:$AM$62,">20") -> 60 | AN72: =COUNTIF(Summary!$AN$3:$AN$62,">20") -> 60 | AO72: =COUNTIF(Summary!$AO$3:$AO$62,">20") -> 60 | AP72: =COUNTIF(Summary!$AP$3:$AP$62,">20") -> 60 | AQ72: =COUNTIF(Summary!$AQ$3:$AQ$62,">20") -> 37 | AR72: =COUNTIF(Summary!$AR$3:$AR$62,">20") -> 60 | AS72: =COUNTIF(Summary!$AS$3:$AS$62,">20") -> 60 | AT72: =COUNTIF(Summary!$AT$3:$AT$62,">20") -> 60 | AU72: =COUNTIF(Summary!$AU$3:$AU$62,">20") -> 59 | AV72: =COUNTIF(Summary!$AV$3:$AV$62,">20") -> 60 | AW72: =COUNTIF(Summary!$AW$3:$AW$62,">20") -> 60
K73: prom | L73: =AVERAGEIF(Summary!$L$3:$L$62,">20") -> 52.416667 | M73: =AVERAGEIF(Summary!$M$3:$M$62,">20") -> 39.942308 | N73: =AVERAGEIF(Summary!$N$3:$N$62,">20") -> 29.25 | O73: =AVERAGEIF(Summary!$O$3:$O$62,">20") -> 49.233333 | P73: =AVERAGEIF(Summary!$P$3:$P$62,">20") -> 27.557692 | Q73: =AVERAGEIF(Summary!$Q$3:$Q$62,">20") -> 41.116667 | R73: =AVERAGEIF(Summary!$R$3:$R$62,">20") -> 49.35 | S73: =AVERAGEIF(Summary!$S$3:$S$62,">20") -> 36.7 | T73: =AVERAGEIF(Summary!$T$3:$T$62,">20") -> 53.266667 | U73: =AVERAGEIF(Summary!$U$3:$U$62,">20") -> 44.216667 | V73: =AVERAGEIF(Summary!$V$3:$V$62,">20") -> 41 | W73: =AVERAGEIF(Summary!$W$3:$W$62,">20") -> 46.2 | X73: =AVERAGEIF(Summary!$X$3:$X$62,">20") -> 42.183333 | Y73: =AVERAGEIF(Summary!$Y$3:$Y$62,">20") -> 48.583333 | Z73: =AVERAGEIF(Summary!$Z$3:$Z$62,">20") -> 50.466667 | AA73: =AVERAGEIF(Summary!$AA$3:$AA$62,">20") -> 41.736842 | AB73: =AVERAGEIF(Summary!$AB$3:$AB$62,">20") -> 49.866667 | AC73: =AVERAGEIF(Summary!$AC$3:$AC$62,">20") -> 41.952381 | AD73: =AVERAGEIF(Summary!$AD$3:$AD$62,">20") -> 47.1 | AE73: =AVERAGEIF(Summary!$AE$3:$AE$62,">20") -> 42.55 | AF73: =AVERAGEIF(Summary!$AF$3:$AF$62,">20") -> 44.416667 | AG73: =AVERAGEIF(Summary!$AG$3:$AG$62,">20") -> 43.440678 | AH73: =AVERAGEIF(Summary!$AH$3:$AH$62,">20") -> 48.666667 | AI73: =AVERAGEIF(Summary!$AI$3:$AI$62,">20") -> 45.983333 | AJ73: =AVERAGEIF(Summary!$AJ$3:$AJ$62,">20") -> 47.55 | AK73: =AVERAGEIF(Summary!$AK$3:$AK$62,">20") -> 45.566667 | AL73: =AVERAGEIF(Summary!$AL$3:$AL$62,">20") -> 50.666667 | AM73: =AVERAGEIF(Summary!$AM$3:$AM$62,">20") -> 44.633333 | AN73: =AVERAGEIF(Summary!$AN$3:$AN$62,">20") -> 48.45 | AO73: =AVERAGEIF(Summary!$AO$3:$AO$62,">20") -> 47.4 | AP73: =AVERAGEIF(Summary!$AP$3:$AP$62,">20") -> 45.316667 | AQ73: =AVERAGEIF(Summary!$AQ$3:$AQ$62,">20") -> 36.621622 | AR73: =AVERAGEIF(Summary!$AR$3:$AR$62,">20") -> 48.966667 | AS73: =AVERAGEIF(Summary!$AS$3:$AS$62,">20") -> 46.15 | AT73: =AVERAGEIF(Summary!$AT$3:$AT$62,">20") -> 48.6 | AU73: =AVERAGEIF(Summary!$AU$3:$AU$62,">20") -> 40.491525 | AV73: =AVERAGEIF(Summary!$AV$3:$AV$62,">20") -> 44.45 | AW73: =AVERAGEIF(Summary!$AW$3:$AW$62,">20") -> 45.866667
K74: Total | L74: =SUM(L72:AW72) -> 2083 | M74: =(60*38)-L74 -> 197 | N74: Mediciones eliminadas
K75: prom.all | L75: =AVERAGE(L73:AW73) -> 44.682273

Sheet Usable
A1: Imagen | B1: U1 | C1: U10 | D1: U11 | E1: U12 | F1: U13 | G1: U14 | H1: U15 | I1: U16 | J1: U17 | K1: U18 | L1: U19 | M1: U2 | N1: U20 | O1: U21 | P1: U22 | Q1: U23 | R1: U24 | S1: U25 | T1: U26 | U1: U27 | V1: U28 | W1: U29 | X1: U3 | Y1: U30 | Z1: U31 | AA1: U32 | AB1: U33 | AC1: U34 | AD1: U35 | AE1: U36 | AF1: U37 | AG1: U38 | AH1: U4 | AI1: U5 | AJ1: U6 | AK1: U7 | AL1: U8 | AM1: U9 | AO1: Imagen | AP1: Total Participantes | AQ1: Total Muestras | AS1: U1 | AT1: U10 | AU1: U11 | AV1: U12 | AW1: U13 | AX1: U14 | AY1: U15 | AZ1: U16 | BA1: U17 | BB1: U18 | BC1: U19 | BD1: U2 | BE1: U20 | BF1: U21 | BG1: U22 | BH1: U23 | BI1: U24 | BJ1: U25 | BK1: U26 | BL1: U27 | BM1: U28 | BN1: U29 | BO1: U3 | BP1: U30 | BQ1: U31 | BR1: U32 | BS1: U33 | BT1: U34 | BU1: U35 | BV1: U36 | BW1: U37 | BX1: U38 | BY1: U4 | BZ1: U5 | CA1: U6 | CB1: U7 | CC1: U8 | CD1: U9
A2: 1 | B2: =IF(Summary!L3>20,1,0) -> 1 | C2: =IF(Summary!M3>20,1,0) -> 1 | D2: =IF(Summary!N3>20,1,0) -> 0 | E2: =IF(Summary!O3>20,1,0) -> 1 | F2: =IF(Summary!P3>20,1,0) -> 1 | G2: =IF(Summary!Q3>20,1,0) -> 1 | H2: =IF(Summary!R3>20,1,0) -> 1 | I2: =IF(Summary!S3>20,1,0) -> 1 | ... AM2: =IF(Summary!AW3>20,1,0) -> 1 | AO2: 1 | AP2: =SUM(B2:AM2) -> 37 | AQ2: =SUM(AS2:CD2) -> 1645 | AS2: =B2*Summary!L3 -> 51 | AT2: =C2*Summary!M3 -> 43 | AU2: =D2*Summary!N3 -> 0 | AV2: =E2*Summary!O3 -> 47 | AW2: =F2*Summary!P3 -> 28 | AX2: =G2*Summary!Q3 -> 42 | AY2: =H2*Summary!R3 -> 53 | AZ2: =I2*Summary!S3 -> 48 | ... CD2: =AM2*Summary!AW3 -> 42
A3: 2 | B3: =IF(Summary!L4>20,1,0) -> 1 | C3: =IF(Summary!M4>20,1,0) -> 1 | D3: =IF(Summary!N4>20,1,0) -> 0 | E3: =IF(Summary!O4>20,1,0) -> 1 | F3: =IF(Summary!P4>20,1,0) -> 1 | G3: =IF(Summary!Q4>20,1,0) -> 1 | H3: =IF(Summary!R4>20,1,0) -> 1 | I3: =IF(Summary!S4>20,1,0) -> 1 | ... AM3: =IF(Summary!AW4>20,1,0) -> 1 | AO3: 2 | AP3: =SUM(B3:AM3) -> 37 | AQ3: =SUM(AS3:CD3) -> 1635 | AS3: =B3*Summary!L4 -> 58 | AT3: =C3*Summary!M4 -> 46 | AU3: =D3*Summary!N4 -> 0 | AV3: =E3*Summary!O4 -> 50 | AW3: =F3*Summary!P4 -> 21 | AX3: =G3*Summary!Q4 -> 38 | AY3: =H3*Summary!R4 -> 50 | AZ3: =I3*Summary!S4 -> 38 | ... CD3: =AM3*Summary!AW4 -> 36
A4: 3 | B4: =IF(Summary!L5>20,1,0) -> 1 | C4: =IF(Summary!M5>20,1,0) -> 1 | D4: =IF(Summary!N5>20,1,0) -> 0 | E4: =IF(Summary!O5>20,1,0) -> 1 | F4: =IF(Summary!P5>20,1,0) -> 1 | G4: =IF(Summary!Q5>20,1,0) -> 1 | H4: =IF(Summary!R5>20,1,0) -> 1 | I4: =IF(Summary!S5>20,1,0) -> 1 | ... AM4: =IF(Summary!AW5>20,1,0) -> 1 | AO4: 3 | AP4: =SUM(B4:AM4) -> 37 | AQ4: =SUM(AS4:CD4) -> 1634 | AS4: =B4*Summary!L5 -> 56 | AT4: =C4*Summary!M5 -> 43 | AU4: =D4*Summary!N5 -> 0 | AV4: =E4*Summary!O5 -> 49 | AW4: =F4*Summary!P5 -> 21 | AX4: =G4*Summary!Q5 -> 40 | AY4: =H4*Summary!R5 -> 52 | AZ4: =I4*Summary!S5 -> 27 | ... CD4: =AM4*Summary!AW5 -> 41
A5: 4 | B5: =IF(Summary!L6>20,1,0) -> 1 | C5: =IF(Summary!M6>20,1,0) -> 1 | D5: =IF(Summary!N6>20,1,0) -> 0 | E5: =IF(Summary!O6>20,1,0) -> 1 | F5: =IF(Summary!P6>20,1,0) -> 0 | G5: =IF(Summary!Q6>20,1,0) -> 1 | H5: =IF(Summary!R6>20,1,0) -> 1 | I5: =IF(Summary!S6>20,1,0) -> 1 | ... AM5: =IF(Summary!AW6>20,1,0) -> 1 | AO5: 4 | AP5: =SUM(B5:AM5) -> 35 | AQ5: =SUM(AS5:CD5) -> 1587 | AS5: =B5*Summary!L6 -> 51 | AT5: =C5*Summary!M6 -> 43 | AU5: =D5*Summary!N6 -> 0 | AV5: =E5*Summary!O6 -> 49 | AW5: =F5*Summary!P6 -> 0 | AX5: =G5*Summary!Q6 -> 39 | AY5: =H5*Summary!R6 -> 47 | AZ5: =I5*Summary!S6 -> 36 | ... CD5: =AM5*Summary!AW6 -> 52
A6: 5 | B6: =IF(Summary!L7>20,1,0) -> 1 | C6: =IF(Summary!M7>20,1,0) -> 1 | D6: =IF(Summary!N7>20,1,0) -> 0 | E6: =IF(Summary!O7>20,1,0) -> 1 | F6: =IF(Summary!P7>20,1,0) -> 0 | G6: =IF(Summary!Q7>20,1,0) -> 1 | H6: =IF(Summary!R7>20,1,0) -> 1 | I6: =IF(Summary!S7>20,1,0) -> 1 | ... AM6: =IF(Summary!AW7>20,1,0) -> 1 | AO6: 5 | AP6: =SUM(B6:AM6) -> 35 | AQ6: =SUM(AS6:CD6) -> 1603 | AS6: =B6*Summary!L7 -> 44 | AT6: =C6*Summary!M7 -> 40 | AU6: =D6*Summary!N7 -> 0 | AV6: =E6*Summary!O7 -> 49 | AW6: =F6*Summary!P7 -> 0 | AX6: =G6*Summary!Q7 -> 48 | AY6: =H6*Summary!R7 -> 50 | AZ6: =I6*Summary!S7 -> 43 | ... CD6: =AM6*Summary!AW7 -> 45
A7: 6 | B7: =IF(Summary!L8>20,1,0) -> 1 | C7: =IF(Summary!M8>20,1,0) -> 1 | D7: =IF(Summary!N8>20,1,0) -> 0 | E7: =IF(Summary!O8>20,1,0) -> 1 | F7: =IF(Summary!P8>20,1,0) -> 1 | G7: =IF(Summary!Q8>20,1,0) -> 1 | H7: =IF(Summary!R8>20,1,0) -> 1 | I7: =IF(Summary!S8>20,1,0) -> 1 | ... AM7: =IF(Summary!AW8>20,1,0) -> 1 | AO7: 6 | AP7: =SUM(B7:AM7) -> 36 | AQ7: =SUM(AS7:CD7) -> 1569 | AS7: =B7*Summary!L8 -> 53 | AT7: =C7*Summary!M8 -> 39 | AU7: =D7*Summary!N8 -> 0 | AV7: =E7*Summary!O8 -> 46 | AW7: =F7*Summary!P8 -> 32 | AX7: =G7*Summary!Q8 -> 32 | AY7: =H7*Summary!R8 -> 47 | AZ7: =I7*Summary!S8 -> 40 | ... CD7: =AM7*Summary!AW8 -> 43
A8: 7 | B8: =IF(Summary!L9>20,1,0) -> 1 | C8: =IF(Summary!M9>20,1,0) -> 1 | D8: =IF(Summary!N9>20,1,0) -> 0 | E8: =IF(Summary!O9>20,1,0) -> 1 | F8: =IF(Summary!P9>20,1,0) -> 1 | G8: =IF(Summary!Q9>20,1,0) -> 1 | H8: =IF(Summary!R9>20,1,0) -> 1 | I8: =IF(Summary!S9>20,1,0) -> 1 | ... AM8: =IF(Summary!AW9>20,1,0) -> 1 | AO8: 7 | AP8: =SUM(B8:AM8) -> 35 | AQ8: =SUM(AS8:CD8) -> 1635 | AS8: =B8*Summary!L9 -> 55 | AT8: =C8*Summary!M9 -> 49 | AU8: =D8*Summary!N9 -> 0 | AV8: =E8*Summary!O9 -> 54 | AW8: =F8*Summary!P9 -> 25 | AX8: =G8*Summary!Q9 -> 48 | AY8: =H8*Summary!R9 -> 39 | AZ8: =I8*Summary!S9 -> 33 | ... CD8: =AM8*Summary!AW9 -> 42
A9: 8 | B9: =IF(Summary!L10>20,1,0) -> 1 | C9: =IF(Summary!M10>20,1,0) -> 1 | D9: =IF(Summary!N10>20,1,0) -> 0 | E9: =IF(Summary!O10>20,1,0) -> 1 | F9: =IF(Summary!P10>20,1,0) -> 1 | G9: =IF(Summary!Q10>20,1,0) -> 1 | H9: =IF(Summary!R10>20,1,0) -> 1 | I9: =IF(Summary!S10>20,1,0) -> 1 | ... AM9: =IF(Summary!AW10>20,1,0) -> 1 | AO9: 8 | AP9: =SUM(B9:AM9) -> 35 | AQ9: =SUM(AS9:CD9) -> 1568 | AS9: =B9*Summary!L10 -> 52 | AT9: =C9*Summary!M10 -> 36 | AU9: =D9*Summary!N10 -> 0 | AV9: =E9*Summary!O10 -> 52 | AW9: =F9*Summary!P10 -> 23 | AX9: =G9*Summary!Q10 -> 45 | AY9: =H9*Summary!R10 -> 52 | AZ9: =I9*Summary!S10 -> 36 | ... CD9: =AM9*Summary!AW10 -> 40
A10: 9 | B10: =IF(Summary!L11>20,1,0) -> 1 | C10: =IF(Summary!M11>20,1,0) -> 1 | D10: =IF(Summary!N11>20,1,0) -> 0 | E10: =IF(Summary!O11>20,1,0) -> 1 | F10: =IF(Summary!P11>20,1,0) -> 1 | G10: =IF(Summary!Q11>20,1,0) -> 1 | H10: =IF(Summary!R11>20,1,0) -> 1 | I10: =IF(Summary!S11>20,1,0) -> 1 | ... AM10: =IF(Summary!AW11>20,1,0) -> 1 | AO10: 9 | AP10: =SUM(B10:AM10) -> 34 | AQ10: =SUM(AS10:CD10) -> 1523 | AS10: =B10*Summary!L11 -> 49 | AT10: =C10*Summary!M11 -> 40 | AU10: =D10*Summary!N11 -> 0 | AV10: =E10*Summary!O11 -> 52 | AW10: =F10*Summary!P11 -> 24 | AX10: =G10*Summary!Q11 -> 41 | AY10: =H10*Summary!R11 -> 37 | AZ10: =I10*Summary!S11 -> 35 | ... CD10: =AM10*Summary!AW11 -> 38
A11: 10 | B11: =IF(Summary!L12>20,1,0) -> 1 | C11: =IF(Summary!M12>20,1,0) -> 1 | D11: =IF(Summary!N12>20,1,0) -> 0 | E11: =IF(Summary!O12>20,1,0) -> 1 | F11: =IF(Summary!P12>20,1,0) -> 1 | G11: =IF(Summary!Q12>20,1,0) -> 1 | H11: =IF(Summary!R12>20,1,0) -> 1 | I11: =IF(Summary!S12>20,1,0) -> 1 | ... AM11: =IF(Summary!AW12>20,1,0) -> 1 | AO11: 10 | AP11: =SUM(B11:AM11) -> 36 | AQ11: =SUM(AS11:CD11) -> 1580 | AS11: =B11*Summary!L12 -> 56 | AT11: =C11*Summary!M12 -> 37 | AU11: =D11*Summary!N12 -> 0 | AV11: =E11*Summary!O12 -> 53 | AW11: =F11*Summary!P12 -> 29 | AX11: =G11*Summary!Q12 -> 40 | AY11: =H11*Summary!R12 -> 46 | AZ11: =I11*Summary!S12 -> 39 | ... CD11: =AM11*Summary!AW12 -> 41
A12: 11 | B12: =IF(Summary!L13>20,1,0) -> 1 | C12: =IF(Summary!M13>20,1,0) -> 1 | D12: =IF(Summary!N13>20,1,0) -> 0 | E12: =IF(Summary!O13>20,1,0) -> 1 | F12: =IF(Summary!P13>20,1,0) -> 1 | G12: =IF(Summary!Q13>20,1,0) -> 1 | H12: =IF(Summary!R13>20,1,0) -> 1 | I12: =IF(Summary!S13>20,1,0) -> 1 | ... AM12: =IF(Summary!AW13>20,1,0) -> 1 | AO12: 11 | AP12: =SUM(B12:AM12) -> 36 | AQ12: =SUM(AS12:CD12) -> 1635 | AS12: =B12*Summary!L13 -> 49 | AT12: =C12*Summary!M13 -> 42 | AU12: =D12*Summary!N13 -> 0 | AV12: =E12*Summary!O13 -> 49 | AW12: =F12*Summary!P13 -> 27 | AX12: =G12*Summary!Q13 -> 42 | AY12: =H12*Summary!R13 -> 51 | AZ12: =I12*Summary!S13 -> 25 | ... CD12: =AM12*Summary!AW13 -> 43
A13: 12 | B13: =IF(Summary!L14>20,1,0) -> 1 | C13: =IF(Summary!M14>20,1,0) -> 1 | D13: =IF(Summary!N14>20,1,0) -> 0 | E13: =IF(Summary!O14>20,1,0) -> 1 | F13: =IF(Summary!P14>20,1,0) -> 0 | G13: =IF(Summary!Q14>20,1,0) -> 1 | H13: =IF(Summary!R14>20,1,0) -> 1 | I13: =IF(Summary!S14>20,1,0) -> 1 | ... AM13: =IF(Summary!AW14>20,1,0) -> 1 | AO13: 12 | AP13: =SUM(B13:AM13) -> 35 | AQ13: =SUM(AS13:CD13) -> 1587 | AS13: =B13*Summary!L14 -> 54 | AT13: =C13*Summary!M14 -> 42 | AU13: =D13*Summary!N14 -> 0 | AV13: =E13*Summary!O14 -> 50 | AW13: =F13*Summary!P14 -> 0 | AX13: =G13*Summary!Q14 -> 29 | AY13: =H13*Summary!R14 -> 52 | AZ13: =I13*Summary!S14 -> 43 | ... CD13: =AM13*Summary!AW14 -> 49
A14: 13 | B14: =IF(Summary!L15>20,1,0) -> 1 | C14: =IF(Summary!M15>20,1,0) -> 1 | D14: =IF(Summary!N15>20,1,0) -> 0 | E14: =IF(Summary!O15>20,1,0) -> 1 | F14: =IF(Summary!P15>20,1,0) -> 1 | G14: =IF(Summary!Q15>20,1,0) -> 1 | H14: =IF(Summary!R15>20,1,0) -> 1 | I14: =IF(Summary!S15>20,1,0) -> 1 | ... AM14: =IF(Summary!AW15>20,1,0) -> 1 | AO14: 13 | AP14: =SUM(B14:AM14) -> 36 | AQ14: =SUM(AS14:CD14) -> 1690 | AS14: =B14*Summary!L15 -> 43 | AT14: =C14*Summary!M15 -> 39 | AU14: =D14*Summary!N15 -> 0 | AV14: =E14*Summary!O15 -> 52 | AW14: =F14*Summary!P15 -> 23 | AX14: =G14*Summary!Q15 -> 43 | AY14: =H14*Summary!R15 -> 52 | AZ14: =I14*Summary!S15 -> 52 | ... CD14: =AM14*Summary!AW15 -> 49
A15: 14 | B15: =IF(Summary!L16>20,1,0) -> 1 | C15: =IF(Summary!M16>20,1,0) -> 1 | D15: 0 | E15: =IF(Summary!O16>20,1,0) -> 1 | F15: =IF(Summary!P16>20,1,0) -> 1 | G15: =IF(Summary!Q16>20,1,0) -> 1 | H15: =IF(Summary!R16>20,1,0) -> 1 | I15: =IF(Summary!S16>20,1,0) -> 1 | J15: =IF(Summary!T16>20,1,0) -> 1 | K15: =IF(Summary!U16>20,1,0) -> 1 | L15: =IF(Summary!V16>20,1,0) -> 1 | ... AM15: =IF(Summary!AW16>20,1,0) -> 1 | AO15: 14 | AP15: =SUM(B15:AM15) -> 36 | AQ15: =SUM(AS15:CD15) -> 1576 | AS15: =B15*Summary!L16 -> 52 | AT15: =C15*Summary!M16 -> 29 | AU15: =D15*Summary!N16 -> 0 | AV15: =E15*Summary!O16 -> 46 | AW15: =F15*Summary!P16 -> 25 | AX15: =G15*Summary!Q16 -> 44 | AY15: =H15*Summary!R16 -> 44 | AZ15: =I15*Summary!S16 -> 43 | ... CD15: =AM15*Summary!AW16 -> 44
A16: 15 | B16: =IF(Summary!L17>20,1,0) -> 1 | C16: =IF(Summary!M17>20,1,0) -> 1 | D16: =IF(Summary!N17>20,1,0) -> 0 | E16: =IF(Summary!O17>20,1,0) -> 1 | F16: =IF(Summary!P17>20,1,0) -> 1 | G16: =IF(Summary!Q17>20,1,0) -> 1 | H16: =IF(Summary!R17>20,1,0) -> 1 | I16: =IF(Summary!S17>20,1,0) -> 1 | ... AM16: =IF(Summary!AW17>20,1,0) -> 1 | AO16: 15 | AP16: =SUM(B16:AM16) -> 36 | AQ16: =SUM(AS16:CD16) -> 1625 | AS16: =B16*Summary!L17 -> 53 | AT16: =C16*Summary!M17 -> 41 | AU16: =D16*Summary!N17 -> 0 | AV16: =E16*Summary!O17 -> 46 | AW16: =F16*Summary!P17 -> 29 | AX16: =G16*Summary!Q17 -> 39 | AY16: =H16*Summary!R17 -> 55 | AZ16: =I16*Summary!S17 -> 36 | ... CD16: =AM16*Summary!AW17 -> 46
A17: 16 | B17: =IF(Summary!L18>20,1,0) -> 1 | C17: =IF(Summary!M18>20,1,0) -> 1 | D17: =IF(Summary!N18>20,1,0) -> 0 | E17: =IF(Summary!O18>20,1,0) -> 1 | F17: =IF(Summary!P18>20,1,0) -> 0 | G17: =IF(Summary!Q18>20,1,0) -> 1 | H17: =IF(Summary!R18>20,1,0) -> 1 | I17: =IF(Summary!S18>20,1,0) -> 1 | ... AM17: =IF(Summary!AW18>20,1,0) -> 1 | AO17: 16 | AP17: =SUM(B17:AM17) -> 35 | AQ17: =SUM(AS17:CD17) -> 1600 | AS17: =B17*Summary!L18 -> 48 | AT17: =C17*Summary!M18 -> 41 | AU17: =D17*Summary!N18 -> 0 | AV17: =E17*Summary!O18 -> 54 | AW17: =F17*Summary!P18 -> 0 | AX17: =G17*Summary!Q18 -> 50 | AY17: =H17*Summary!R18 -> 50 | AZ17: =I17*Summary!S18 -> 46 | ... CD17: =AM17*Summary!AW18 -> 38
A18: 17 | B18: =IF(Summary!L19>20,1,0) -> 1 | C18: =IF(Summary!M19>20,1,0) -> 1 | D18: =IF(Summary!N19>20,1,0) -> 0 | E18: =IF(Summary!O19>20,1,0) -> 1 | F18: =IF(Summary!P19>20,1,0) -> 1 | G18: =IF(Summary!Q19>20,1,0) -> 1 | H18: =IF(Summary!R19>20,1,0) -> 1 | I18: =IF(Summary!S19>20,1,0) -> 1 | ... AM18: =IF(Summary!AW19>20,1,0) -> 1 | AO18: 17 | AP18: =SUM(B18:AM18) -> 36 | AQ18: =SUM(AS18:CD18) -> 1686 | AS18: =B18*Summary!L19 -> 56 | AT18: =C18*Summary!M19 -> 41 | AU18: =D18*Summary!N19 -> 0 | AV18: =E18*Summary!O19 -> 50 | AW18: =F18*Summary!P19 -> 29 | AX18: =G18*Summary!Q19 -> 44 | AY18: =H18*Summary!R19 -> 47 | AZ18: =I18*Summary!S19 -> 47 | ... CD18: =AM18*Summary!AW19 -> 48
A19: 18 | B19: =IF(Summary!L20>20,1,0) -> 1 | C19: =IF(Summary!M20>20,1,0) -> 1 | D19: =IF(Summary!N20>20,1,0) -> 0 | E19: =IF(Summary!O20>20,1,0) -> 1 | F19: =IF(Summary!P20>20,1,0) -> 1 | G19: =IF(Summary!Q20>20,1,0) -> 1 | H19: =IF(Summary!R20>20,1,0) -> 1 | I19: =IF(Summary!S20>20,1,0) -> 1 | ... AM19: =IF(Summary!AW20>20,1,0) -> 1 | AO19: 18 | AP19: =SUM(B19:AM19) -> 36 | AQ19: =SUM(AS19:CD19) -> 1579 | AS19: =B19*Summary!L20 -> 56 | AT19: =C19*Summary!M20 -> 45 | AU19: =D19*Summary!N20 -> 0 | AV19: =E19*Summary!O20 -> 43 | AW19: =F19*Summary!P20 -> 25 | AX19: =G19*Summary!Q20 -> 47 | AY19: =H19*Summary!R20 -> 51 | AZ19: =I19*Summary!S20 -> 45 | ... CD19: =AM19*Summary!AW20 -> 40
A20: 19 | B20: =IF(Summary!L21>20,1,0) -> 1 | C20: =IF(Summary!M21>20,1,0) -> 1 | D20: 0 | E20: =IF(Summary!O21>20,1,0) -> 1 | F20: =IF(Summary!P21>20,1,0) -> 1 | G20: =IF(Summary!Q21>20,1,0) -> 1 | H20: =IF(Summary!R21>20,1,0) -> 1 | I20: =IF(Summary!S21>20,1,0) -> 1 | J20: =IF(Summary!T21>20,1,0) -> 1 | K20: =IF(Summary!U21>20,1,0) -> 1 | L20: =IF(Summary!V21>20,1,0) -> 1 | ... AM20: =IF(Summary!AW21>20,1,0) -> 1 | AO20: 19 | AP20: =SUM(B20:AM20) -> 36 | AQ20: =SUM(AS20:CD20) -> 1648 | AS20: =B20*Summary!L21 -> 49 | AT20: =C20*Summary!M21 -> 34 | AU20: =D20*Summary!N21 -> 0 | AV20: =E20*Summary!O21 -> 49 | AW20: =F20*Summary!P21 -> 35 | AX20: =G20*Summary!Q21 -> 41 | AY20: =H20*Summary!R21 -> 55 | AZ20: =I20*Summary!S21 -> 48 | ... CD20: =AM20*Summary!AW21 -> 55
A21: 20 | B21: =IF(Summary!L22>20,1,0) -> 1 | C21: =IF(Summary!M22>20,1,0) -> 1 | D21: 0 | E21: =IF(Summary!O22>20,1,0) -> 1 | F21: =IF(Summary!P22>20,1,0) -> 1 | G21: =IF(Summary!Q22>20,1,0) -> 1 | H21: =IF(Summary!R22>20,1,0) -> 1 | I21: =IF(Summary!S22>20,1,0) -> 1 | J21: =IF(Summary!T22>20,1,0) -> 1 | K21: =IF(Summary!U22>20,1,0) -> 1 | L21: =IF(Summary!V22>20,1,0) -> 1 | ... AM21: =IF(Summary!AW22>20,1,0) -> 1 | AO21: 20 | AP21: =SUM(B21:AM21) -> 36 | AQ21: =SUM(AS21:CD21) -> 1709 | AS21: =B21*Summary!L22 -> 58 | AT21: =C21*Summary!M22 -> 45 | AU21: =D21*Summary!N22 -> 0 | AV21: =E21*Summary!O22 -> 50 | AW21: =F21*Summary!P22 -> 31 | AX21: =G21*Summary!Q22 -> 42 | AY21: =H21*Summary!R22 -> 48 | AZ21: =I21*Summary!S22 -> 23 | ... CD21: =AM21*Summary!AW22 -> 55
A22: 21 | B22: =IF(Summary!L23>20,1,0) -> 1 | C22: =IF(Summary!M23>20,1,0) -> 1 | D22: =IF(Summary!N23>20,1,0) -> 0 | E22: =IF(Summary!O23>20,1,0) -> 1 | F22: =IF(Summary!P23>20,1,0) -> 1 | G22: =IF(Summary!Q23>20,1,0) -> 1 | H22: =IF(Summary!R23>20,1,0) -> 1 | I22: =IF(Summary!S23>20,1,0) -> 1 | ... AM22: =IF(Summary!AW23>20,1,0) -> 1 | AO22: 21 | AP22: =SUM(B22:AM22) -> 36 | AQ22: =SUM(AS22:CD22) -> 1593 | AS22: =B22*Summary!L23 -> 55 | AT22: =C22*Summary!M23 -> 33 | AU22: =D22*Summary!N23 -> 0 | AV22: =E22*Summary!O23 -> 51 | AW22: =F22*Summary!P23 -> 22 | AX22: =G22*Summary!Q23 -> 36 | AY22: =H22*Summary!R23 -> 48 | AZ22: =I22*Summary!S23 -> 51 | ... CD22: =AM22*Summary!AW23 -> 48
A23: 22 | B23: =IF(Summary!L24>20,1,0) -> 1 | C23: =IF(Summary!M24>20,1,0) -> 1 | D23: =IF(Summary!N24>20,1,0) -> 0 | E23: =IF(Summary!O24>20,1,0) -> 1 | F23: =IF(Summary!P24>20,1,0) -> 1 | G23: =IF(Summary!Q24>20,1,0) -> 1 | H23: =IF(Summary!R24>20,1,0) -> 1 | I23: =IF(Summary!S24>20,1,0) -> 1 | ... AM23: =IF(Summary!AW24>20,1,0) -> 1 | AO23: 22 | AP23: =SUM(B23:AM23) -> 35 | AQ23: =SUM(AS23:CD23) -> 1602 | AS23: =B23*Summary!L24 -> 50 | AT23: =C23*Summary!M24 -> 45 | AU23: =D23*Summary!N24 -> 0 | AV23: =E23*Summary!O24 -> 51 | AW23: =F23*Summary!P24 -> 34 | AX23: =G23*Summary!Q24 -> 21 | AY23: =H23*Summary!R24 -> 48 | AZ23: =I23*Summary!S24 -> 33 | ... CD23: =AM23*Summary!AW24 -> 52
A24: 23 | B24: =IF(Summary!L25>20,1,0) -> 1 | C24: =IF(Summary!M25>20,1,0) -> 1 | D24: =IF(Summary!N25>20,1,0) -> 0 | E24: =IF(Summary!O25>20,1,0) -> 1 | F24: =IF(Summary!P25>20,1,0) -> 1 | G24: =IF(Summary!Q25>20,1,0) -> 1 | H24: =IF(Summary!R25>20,1,0) -> 1 | I24: =IF(Summary!S25>20,1,0) -> 1 | ... AM24: =IF(Summary!AW25>20,1,0) -> 1 | AO24: 23 | AP24: =SUM(B24:AM24) -> 35 | AQ24: =SUM(AS24:CD24) -> 1642 | AS24: =B24*Summary!L25 -> 55 | AT24: =C24*Summary!M25 -> 38 | AU24: =D24*Summary!N25 -> 0 | AV24: =E24*Summary!O25 -> 55 | AW24: =F24*Summary!P25 -> 30 | AX24: =G24*Summary!Q25 -> 37 | AY24: =H24*Summary!R25 -> 51 | AZ24: =I24*Summary!S25 -> 37 | ... CD24: =AM24*Summary!AW25 -> 51
A25: 24 | B25: =IF(Summary!L26>20,1,0) -> 1 | C25: =IF(Summary!M26>20,1,0) -> 1 | D25: =IF(Summary!N26>20,1,0) -> 0 | E25: =IF(Summary!O26>20,1,0) -> 1 | F25: =IF(Summary!P26>20,1,0) -> 1 | G25: =IF(Summary!Q26>20,1,0) -> 1 | H25: =IF(Summary!R26>20,1,0) -> 1 | I25: =IF(Summary!S26>20,1,0) -> 1 | ... AM25: =IF(Summary!AW26>20,1,0) -> 1 | AO25: 24 | AP25: =SUM(B25:AM25) -> 36 | AQ25: =SUM(AS25:CD25) -> 1594 | AS25: =B25*Summary!L26 -> 55 | AT25: =C25*Summary!M26 -> 33 | AU25: =D25*Summary!N26 -> 0 | AV25: =E25*Summary!O26 -> 47 | AW25: =F25*Summary!P26 -> 30 | AX25: =G25*Summary!Q26 -> 44 | AY25: =H25*Summary!R26 -> 49 | AZ25: =I25*Summary!S26 -> 46 | ... CD25: =AM25*Summary!AW26 -> 51
A26: 25 | B26: =IF(Summary!L27>20,1,0) -> 1 | C26: =IF(Summary!M27>20,1,0) -> 1 | D26: =IF(Summary!N27>20,1,0) -> 0 | E26: =IF(Summary!O27>20,1,0) -> 1 | F26: =IF(Summary!P27>20,1,0) -> 1 | G26: =IF(Summary!Q27>20,1,0) -> 1 | H26: =IF(Summary!R27>20,1,0) -> 1 | I26: =IF(Summary!S27>20,1,0) -> 1 | ... AM26: =IF(Summary!AW27>20,1,0) -> 1 | AO26: 25 | AP26: =SUM(B26:AM26) -> 35 | AQ26: =SUM(AS26:CD26) -> 1580 | AS26: =B26*Summary!L27 -> 55 | AT26: =C26*Summary!M27 -> 39 | AU26: =D26*Summary!N27 -> 0 | AV26: =E26*Summary!O27 -> 50 | AW26: =F26*Summary!P27 -> 29 | AX26: =G26*Summary!Q27 -> 41 | AY26: =H26*Summary!R27 -> 49 | AZ26: =I26*Summary!S27 -> 32 | ... CD26: =AM26*Summary!AW27 -> 49
A27: 26 | B27: =IF(Summary!L28>20,1,0) -> 1 | C27: =IF(Summary!M28>20,1,0) -> 1 | D27: =IF(Summary!N28>20,1,0) -> 0 | E27: =IF(Summary!O28>20,1,0) -> 1 | F27: =IF(Summary!P28>20,1,0) -> 1 | G27: =IF(Summary!Q28>20,1,0) -> 1 | H27: =IF(Summary!R28>20,1,0) -> 1 | I27: =IF(Summary!S28>20,1,0) -> 1 | ... AM27: =IF(Summary!AW28>20,1,0) -> 1 | AO27: 26 | AP27: =SUM(B27:AM27) -> 35 | AQ27: =SUM(AS27:CD27) -> 1542 | AS27: =B27*Summary!L28 -> 48 | AT27: =C27*Summary!M28 -> 32 | AU27: =D27*Summary!N28 -> 0 | AV27: =E27*Summary!O28 -> 47 | AW27: =F27*Summary!P28 -> 31 | AX27: =G27*Summary!Q28 -> 40 | AY27: =H27*Summary!R28 -> 53 | AZ27: =I27*Summary!S28 -> 37 | ... CD27: =AM27*Summary!AW28 -> 50
A28: 27 | B28: =IF(Summary!L29>20,1,0) -> 1 | C28: =IF(Summary!M29>20,1,0) -> 1 | D28: =IF(Summary!N29>20,1,0) -> 0 | E28: =IF(Summary!O29>20,1,0) -> 1 | F28: =IF(Summary!P29>20,1,0) -> 1 | G28: =IF(Summary!Q29>20,1,0) -> 1 | H28: =IF(Summary!R29>20,1,0) -> 1 | I28: =IF(Summary!S29>20,1,0) -> 1 | ... AM28: =IF(Summary!AW29>20,1,0) -> 1 | AO28: 27 | AP28: =SUM(B28:AM28) -> 34 | AQ28: =SUM(AS28:CD28) -> 1577 | AS28: =B28*Summary!L29 -> 61 | AT28: =C28*Summary!M29 -> 44 | AU28: =D28*Summary!N29 -> 0 | AV28: =E28*Summary!O29 -> 50 | AW28: =F28*Summary!P29 -> 32 | AX28: =G28*Summary!Q29 -> 42 | AY28: =H28*Summary!R29 -> 49 | AZ28: =I28*Summary!S29 -> 43 | ... CD28: =AM28*Summary!AW29 -> 44
A29: 28 | B29: =IF(Summary!L30>20,1,0) -> 1 | C29: =IF(Summary!M30>20,1,0) -> 1 | D29: =IF(Summary!N30>20,1,0) -> 0 | E29: =IF(Summary!O30>20,1,0) -> 1 | F29: =IF(Summary!P30>20,1,0) -> 1 | G29: =IF(Summary!Q30>20,1,0) -> 1 | H29: =IF(Summary!R30>20,1,0) -> 1 | I29: =IF(Summary!S30>20,1,0) -> 1 | ... AM29: =IF(Summary!AW30>20,1,0) -> 1 | AO29: 28 | AP29: =SUM(B29:AM29) -> 34 | AQ29: =SUM(AS29:CD29) -> 1565 | AS29: =B29*Summary!L30 -> 58 | AT29: =C29*Summary!M30 -> 52 | AU29: =D29*Summary!N30 -> 0 | AV29: =E29*Summary!O30 -> 46 | AW29: =F29*Summary!P30 -> 22 | AX29: =G29*Summary!Q30 -> 43 | AY29: =H29*Summary!R30 -> 54 | AZ29: =I29*Summary!S30 -> 45 | ... CD29: =AM29*Summary!AW30 -> 41
A30: 29 | B30: =IF(Summary!L31>20,1,0) -> 1 | C30: =IF(Summary!M31>20,1,0) -> 1 | D30: =IF(Summary!N31>20,1,0) -> 0 | E30: =IF(Summary!O31>20,1,0) -> 1 | F30: =IF(Summary!P31>20,1,0) -> 1 | G30: =IF(Summary!Q31>20,1,0) -> 1 | H30: =IF(Summary!R31>20,1,0) -> 1 | I30: =IF(Summary!S31>20,1,0) -> 1 | ... AM30: =IF(Summary!AW31>20,1,0) -> 1 | AO30: 29 | AP30: =SUM(B30:AM30) -> 34 | AQ30: =SUM(AS30:CD30) -> 1510 | AS30: =B30*Summary!L31 -> 57 | AT30: =C30*Summary!M31 -> 44 | AU30: =D30*Summary!N31 -> 0 | AV30: =E30*Summary!O31 -> 45 | AW30: =F30*Summary!P31 -> 25 | AX30: =G30*Summary!Q31 -> 45 | AY30: =H30*Summary!R31 -> 52 | AZ30: =I30*Summary!S31 -> 41 | ... CD30: =AM30*Summary!AW31 -> 48
A31: 30 | B31: =IF(Summary!L32>20,1,0) -> 1 | C31: =IF(Summary!M32>20,1,0) -> 1 | D31: =IF(Summary!N32>20,1,0) -> 0 | E31: =IF(Summary!O32>20,1,0) -> 1 | F31: =IF(Summary!P32>20,1,0) -> 1 | G31: =IF(Summary!Q32>20,1,0) -> 1 | H31: =IF(Summary!R32>20,1,0) -> 1 | I31: =IF(Summary!S32>20,1,0) -> 1 | ... AM31: =IF(Summary!AW32>20,1,0) -> 1 | AO31: 30 | AP31: =SUM(B31:AM31) -> 35 | AQ31: =SUM(AS31:CD31) -> 1534 | AS31: =B31*Summary!L32 -> 47 | AT31: =C31*Summary!M32 -> 28 | AU31: =D31*Summary!N32 -> 0 | AV31: =E31*Summary!O32 -> 51 | AW31: =F31*Summary!P32 -> 24 | AX31: =G31*Summary!Q32 -> 40 | AY31: =H31*Summary!R32 -> 51 | AZ31: =I31*Summary!S32 -> 27 | ... CD31: =AM31*Summary!AW32 -> 52
A32: 31 | B32: =IF(Summary!L33>20,1,0) -> 1 | C32: =IF(Summary!M33>20,1,0) -> 1 | D32: =IF(Summary!N33>20,1,0) -> 0 | E32: =IF(Summary!O33>20,1,0) -> 1 | F32: =IF(Summary!P33>20,1,0) -> 1 | G32: =IF(Summary!Q33>20,1,0) -> 1 | H32: =IF(Summary!R33>20,1,0) -> 1 | I32: =IF(Summary!S33>20,1,0) -> 1 | ... AM32: =IF(Summary!AW33>20,1,0) -> 1 | AO32: 31 | AP32: =SUM(B32:AM32) -> 35 | AQ32: =SUM(AS32:CD32) -> 1656 | AS32: =B32*Summary!L33 -> 56 | AT32: =C32*Summary!M33 -> 49 | AU32: =D32*Summary!N33 -> 0 | AV32: =E32*Summary!O33 -> 52 | AW32: =F32*Summary!P33 -> 28 | AX32: =G32*Summary!Q33 -> 47 | AY32: =H32*Summary!R33 -> 52 | AZ32: =I32*Summary!S33 -> 21 | ... CD32: =AM32*Summary!AW33 -> 52
A33: 32 | B33: =IF(Summary!L34>20,1,0) -> 1 | C33: =IF(Summary!M34>20,1,0) -> 1 | D33: =IF(Summary!N34>20,1,0) -> 0 | E33: =IF(Summary!O34>20,1,0) -> 1 | F33: =IF(Summary!P34>20,1,0) -> 1 | G33: =IF(Summary!Q34>20,1,0) -> 1 | H33: =IF(Summary!R34>20,1,0) -> 1 | I33: =IF(Summary!S34>20,1,0) -> 1 | ... AM33: =IF(Summary!AW34>20,1,0) -> 1 | AO33: 32 | AP33: =SUM(B33:AM33) -> 35 | AQ33: =SUM(AS33:CD33) -> 1572 | AS33: =B33*Summary!L34 -> 50 | AT33: =C33*Summary!M34 -> 42 | AU33: =D33*Summary!N34 -> 0 | AV33: =E33*Summary!O34 -> 47 | AW33: =F33*Summary!P34 -> 24 | AX33: =G33*Summary!Q34 -> 41 | AY33: =H33*Summary!R34 -> 45 | AZ33: =I33*Summary!S34 -> 34 | ... CD33: =AM33*Summary!AW34 -> 40
A34: 33 | B34: =IF(Summary!L35>20,1,0) -> 1 | C34: =IF(Summary!M35>20,1,0) -> 1 | D34: 0 | E34: =IF(Summary!O35>20,1,0) -> 1 | F34: =IF(Summary!P35>20,1,0) -> 1 | G34: =IF(Summary!Q35>20,1,0) -> 1 | H34: =IF(Summary!R35>20,1,0) -> 1 | I34: =IF(Summary!S35>20,1,0) -> 1 | J34: =IF(Summary!T35>20,1,0) -> 1 | K34: =IF(Summary!U35>20,1,0) -> 1 | L34: =IF(Summary!V35>20,1,0) -> 1 | ... AM34: =IF(Summary!AW35>20,1,0) -> 1 | AO34: 33 | AP34: =SUM(B34:AM34) -> 34 | AQ34: =SUM(AS34:CD34) -> 1525 | AS34: =B34*Summary!L35 -> 47 | AT34: =C34*Summary!M35 -> 40 | AU34: =D34*Summary!N35 -> 0 | AV34: =E34*Summary!O35 -> 47 | AW34: =F34*Summary!P35 -> 25 | AX34: =G34*Summary!Q35 -> 31 | AY34: =H34*Summary!R35 -> 49 | AZ34: =I34*Summary!S35 -> 41 | ... CD34: =AM34*Summary!AW35 -> 49
A35: 34 | B35: =IF(Summary!L36>20,1,0) -> 1 | C35: =IF(Summary!M36>20,1,0) -> 1 | D35: =IF(Summary!N36>20,1,0) -> 0 | E35: =IF(Summary!O36>20,1,0) -> 1 | F35: =IF(Summary!P36>20,1,0) -> 0 | G35: =IF(Summary!Q36>20,1,0) -> 1 | H35: =IF(Summary!R36>20,1,0) -> 1 | I35: =IF(Summary!S36>20,1,0) -> 1 | ... AM35: =IF(Summary!AW36>20,1,0) -> 1 | AO35: 34 | AP35: =SUM(B35:AM35) -> 33 | AQ35: =SUM(AS35:CD35) -> 1443 | AS35: =B35*Summary!L36 -> 51 | AT35: =C35*Summary!M36 -> 35 | AU35: =D35*Summary!N36 -> 0 | AV35: =E35*Summary!O36 -> 47 | AW35: =F35*Summary!P36 -> 0 | AX35: =G35*Summary!Q36 -> 43 | AY35: =H35*Summary!R36 -> 45 | AZ35: =I35*Summary!S36 -> 33 | ... CD35: =AM35*Summary!AW36 -> 49
A36: 35 | B36: =IF(Summary!L37>20,1,0) -> 1 | C36: =IF(Summary!M37>20,1,0) -> 1 | D36: =IF(Summary!N37>20,1,0) -> 0 | E36: =IF(Summary!O37>20,1,0) -> 1 | F36: =IF(Summary!P37>20,1,0) -> 1 | G36: =IF(Summary!Q37>20,1,0) -> 1 | H36: =IF(Summary!R37>20,1,0) -> 1 | I36: =IF(Summary!S37>20,1,0) -> 1 | ... AM36: =IF(Summary!AW37>20,1,0) -> 1 | AO36: 35 | AP36: =SUM(B36:AM36) -> 35 | AQ36: =SUM(AS36:CD36) -> 1587 | AS36: =B36*Summary!L37 -> 42 | AT36: =C36*Summary!M37 -> 44 | AU36: =D36*Summary!N37 -> 0 | AV36: =E36*Summary!O37 -> 45 | AW36: =F36*Summary!P37 -> 37 | AX36: =G36*Summary!Q37 -> 41 | AY36: =H36*Summary!R37 -> 49 | AZ36: =I36*Summary!S37 -> 29 | ... CD36: =AM36*Summary!AW37 -> 46
A37: 36 | B37: =IF(Summary!L38>20,1,0) -> 1 | C37: =IF(Summary!M38>20,1,0) -> 1 | D37: =IF(Summary!N38>20,1,0) -> 0 | E37: =IF(Summary!O38>20,1,0) -> 1 | F37: =IF(Summary!P38>20,1,0) -> 1 | G37: =IF(Summary!Q38>20,1,0) -> 1 | H37: =IF(Summary!R38>20,1,0) -> 1 | I37: =IF(Summary!S38>20,1,0) -> 1 | ... AM37: =IF(Summary!AW38>20,1,0) -> 1 | AO37: 36 | AP37: =SUM(B37:AM37) -> 35 | AQ37: =SUM(AS37:CD37) -> 1613 | AS37: =B37*Summary!L38 -> 55 | AT37: =C37*Summary!M38 -> 42 | AU37: =D37*Summary!N38 -> 0 | AV37: =E37*Summary!O38 -> 51 | AW37: =F37*Summary!P38 -> 26 | AX37: =G37*Summary!Q38 -> 39 | AY37: =H37*Summary!R38 -> 52 | AZ37: =I37*Summary!S38 -> 35 | ... CD37: =AM37*Summary!AW38 -> 49
A38: 37 | B38: =IF(Summary!L39>20,1,0) -> 1 | C38: =IF(Summary!M39>20,1,0) -> 1 | D38: =IF(Summary!N39>20,1,0) -> 0 | E38: =IF(Summary!O39>20,1,0) -> 1 | F38: =IF(Summary!P39>20,1,0) -> 1 | G38: =IF(Summary!Q39>20,1,0) -> 1 | H38: =IF(Summary!R39>20,1,0) -> 1 | I38: =IF(Summary!S39>20,1,0) -> 1 | ... AM38: =IF(Summary!AW39>20,1,0) -> 1 | AO38: 37 | AP38: =SUM(B38:AM38) -> 35 | AQ38: =SUM(AS38:CD38) -> 1618 | AS38: =B38*Summary!L39 -> 56 | AT38: =C38*Summary!M39 -> 42 | AU38: =D38*Summary!N39 -> 0 | AV38: =E38*Summary!O39 -> 50 | AW38: =F38*Summary!P39 -> 33 | AX38: =G38*Summary!Q39 -> 38 | AY38: =H38*Summary!R39 -> 47 | AZ38: =I38*Summary!S39 -> 23 | ... CD38: =AM38*Summary!AW39 -> 46
A39: 38 | B39: =IF(Summary!L40>20,1,0) -> 1 | C39: =IF(Summary!M40>20,1,0) -> 1 | D39: =IF(Summary!N40>20,1,0) -> 0 | E39: =IF(Summary!O40>20,1,0) -> 1 | F39: =IF(Summary!P40>20,1,0) -> 1 | G39: =IF(Summary!Q40>20,1,0) -> 1 | H39: =IF(Summary!R40>20,1,0) -> 1 | I39: =IF(Summary!S40>20,1,0) -> 0 | ... AM39: =IF(Summary!AW40>20,1,0) -> 1 | AO39: 38 | AP39: =SUM(B39:AM39) -> 34 | AQ39: =SUM(AS39:CD39) -> 1519 | AS39: =B39*Summary!L40 -> 50 | AT39: =C39*Summary!M40 -> 40 | AU39: =D39*Summary!N40 -> 0 | AV39: =E39*Summary!O40 -> 47 | AW39: =F39*Summary!P40 -> 24 | AX39: =G39*Summary!Q40 -> 41 | AY39: =H39*Summary!R40 -> 49 | AZ39: =I39*Summary!S40 -> 0 | ... CD39: =AM39*Summary!AW40 -> 50
A40: 39 | B40: =IF(Summary!L41>20,1,0) -> 1 | C40: =IF(Summary!M41>20,1,0) -> 1 | D40: =IF(Summary!N41>20,1,0) -> 0 | E40: =IF(Summary!O41>20,1,0) -> 1 | F40: =IF(Summary!P41>20,1,0) -> 1 | G40: =IF(Summary!Q41>20,1,0) -> 1 | H40: =IF(Summary!R41>20,1,0) -> 1 | I40: =IF(Summary!S41>20,1,0) -> 0 | ... AM40: =IF(Summary!AW41>20,1,0) -> 1 | AO40: 39 | AP40: =SUM(B40:AM40) -> 33 | AQ40: =SUM(AS40:CD40) -> 1530 | AS40: =B40*Summary!L41 -> 58 | AT40: =C40*Summary!M41 -> 42 | AU40: =D40*Summary!N41 -> 0 | AV40: =E40*Summary!O41 -> 49 | AW40: =F40*Summary!P41 -> 25 | AX40: =G40*Summary!Q41 -> 45 | AY40: =H40*Summary!R41 -> 52 | AZ40: =I40*Summary!S41 -> 0 | ... CD40: =AM40*Summary!AW41 -> 43
...

Sheet QA
